Workbook

Sheet January
A1: branchname | B1: ITEM TYPE | C1: TOTAL ITEMS | D1: ADULT ITEMS | E1: YOUNG ADULT ITEMS | F1: JUVENILE ITEMS | G1: TOTAL ADDED LM | H1: ADULT ADDED LM | I1: YOUNG ADULT ADDED LM | J1: JUVENILE ADDED LM | K1: TOTAL DELETED LM | L1: ADULT DELETED LM | M1: YOUNG ADULT DELETED LM | N1: JUVENILE DELETED LM
A2: Atchison Public Library | B2: (Unclassified)
A3: Atchison Public Library | B3: Audiobook (CDs or cassettes) | C3: 2538 | D3: 2476 | E3: 2 | F3: 60 | K3: 1
A4: Atchison Public Library | B4: Audiobook (digital media)
A5: Atchison Public Library | B5: Audiobook (new) | C5: 37 | D5: 37 | G5: 8 | H5: 8
A6: Atchison Public Library | B6: Audiobook (preloaded player) | C6: 7 | D6: 7 | G6: 7 | H6: 7
A7: Atchison Public Library | B7: Book | C7: 51303 | D7: 31833 | E7: 4919 | F7: 14551 | G7: 31 | H7: 17 | J7: 14 | K7: 240
A8: Atchison Public Library | B8: Book - School District 454
A9: Atchison Public Library | B9: Book (local requests only)
A10: Atchison Public Library | B10: Book (new) | C10: 1053 | D10: 659 | E10: 114 | F10: 280 | G10: 149 | H10: 121 | J10: 28 | K10: 1
A11: Atchison Public Library | B11: Book (no requests allowed)
A12: Atchison Public Library | B12: Book club set
A13: Atchison Public Library | B13: Bundle
A14: Atchison Public Library | B14: Computers and internet - Laptop computer
A15: Atchison Public Library | B15: Computers and internet - Launchpad tablet | C15: 1 | F15: 1
A16: Atchison Public Library | B16: Computers and internet - Public computer
A17: Atchison Public Library | B17: Computers and internet - Software
A18: Atchison Public Library | B18: Computers and internet - Tablets, e-readers, and personal computing devices
A19: Atchison Public Library | B19: Computers and internet - Wireless internet hotspot
A20: Atchison Public Library | B20: E-content - Digital content
A21: Atchison Public Library | B21: Inter-library loan | C21: 55 | D21: 50 | F21: 5 | G21: 12 | H21: 12 | K21: 32 | L21: 7
A22: Atchison Public Library | B22: Inter-library loan - 07 day loan
A23: Atchison Public Library | B23: Inter-library loan - 14 day loan
A24: Atchison Public Library | B24: Inter-library loan - 21 day loan
A25: Atchison Public Library | B25: Inter-library loan - 28 day loan
A26: Atchison Public Library | B26: Key
A27: Atchison Public Library | B27: Kit or multi-part set | C27: 24 | D27: 5 | E27: 1 | F27: 18
A28: Atchison Public Library | B28: Magazine
A29: Atchison Public Library | B29: Magazine (new)
A30: Atchison Public Library | B30: Music | C30: 3 | D30: 3
A31: Atchison Public Library | B31: Pamphlet
A32: Atchison Public Library | B32: Reference material | C32: 1126 | D32: 1124 | F32: 2 | G32: 5 | H32: 5
A33: Atchison Public Library | B33: Reserve desk - Highland Community College
A34: Atchison Public Library | B34: Room
A35: Atchison Public Library | B35: Special collections (local requests only) | C35: 180 | D35: 122 | F35: 58 | K35: 2
A36: Atchison Public Library | B36: Special collections (no requests allowed) | C36: 7 | D36: 5 | E36: 1 | F36: 1
A37: Atchison Public Library | B37: Story walk
A38: Atchison Public Library | B38: Things - Artwork
A39: Atchison Public Library | B39: Things - Audio-visual equipment | C39: 7 | F39: 7 | G39: 3 | J39: 3
A40: Atchison Public Library | B40: Things - Bicycles (and bicycle accessories)
...

Sheet February
A1: branchname | B1: ITEM TYPE | C1: TOTAL ITEMS | D1: ADULT ITEMS | E1: YOUNG ADULT ITEMS | F1: JUVENILE ITEMS | G1: TOTAL ADDED LM | H1: ADULT ADDED LM | I1: YOUNG ADULT ADDED LM | J1: JUVENILE ADDED LM | K1: TOTAL DELETED LM | L1: ADULT DELETED LM | M1: YOUNG ADULT DELETED LM | N1: JUVENILE DELETED LM
A2: Atchison Public Library | B2: (Unclassified)
A3: Atchison Public Library | B3: Audiobook (CDs or cassettes) | C3: 2541 | D3: 2479 | E3: 2 | F3: 60
A4: Atchison Public Library | B4: Audiobook (digital media)
A5: Atchison Public Library | B5: Audiobook (new) | C5: 34 | D5: 34
A6: Atchison Public Library | B6: Audiobook (preloaded player) | C6: 7 | D6: 7
A7: Atchison Public Library | B7: Book | C7: 51419 | D7: 31948 | E7: 4946 | F7: 14525 | G7: 23 | H7: 20 | I7: 1 | J7: 2 | K7: 119
A8: Atchison Public Library | B8: Book - School District 454
A9: Atchison Public Library | B9: Book (local requests only)
A10: Atchison Public Library | B10: Book (new) | C10: 1016 | D10: 666 | E10: 112 | F10: 238 | G10: 186 | H10: 155 | I10: 31 | K10: 6
A11: Atchison Public Library | B11: Book (no requests allowed)
A12: Atchison Public Library | B12: Book club set
A13: Atchison Public Library | B13: Bundle
A14: Atchison Public Library | B14: Computers and internet - Laptop computer
A15: Atchison Public Library | B15: Computers and internet - Launchpad tablet | C15: 1 | F15: 1
A16: Atchison Public Library | B16: Computers and internet - Public computer
A17: Atchison Public Library | B17: Computers and internet - Software
A18: Atchison Public Library | B18: Computers and internet - Tablets, e-readers, and personal computing devices
A19: Atchison Public Library | B19: Computers and internet - Wireless internet hotspot
A20: Atchison Public Library | B20: E-content - Digital content
A21: Atchison Public Library | B21: Inter-library loan | C21: 53 | D21: 48 | F21: 5 | G21: 12 | H21: 12 | K21: 20 | L21: 7
A22: Atchison Public Library | B22: Inter-library loan - 07 day loan
A23: Atchison Public Library | B23: Inter-library loan - 14 day loan
A24: Atchison Public Library | B24: Inter-library loan - 21 day loan
A25: Atchison Public Library | B25: Inter-library loan - 28 day loan
A26: Atchison Public Library | B26: Key
A27: Atchison Public Library | B27: Kit or multi-part set | C27: 24 | D27: 5 | E27: 1 | F27: 18
A28: Atchison Public Library | B28: Magazine
A29: Atchison Public Library | B29: Magazine (new)
A30: Atchison Public Library | B30: Music | C30: 3 | D30: 3
A31: Atchison Public Library | B31: Pamphlet
A32: Atchison Public Library | B32: Reference material | C32: 1126 | D32: 1124 | F32: 2
A33: Atchison Public Library | B33: Reserve desk - Highland Community College
A34: Atchison Public Library | B34: Room
A35: Atchison Public Library | B35: Special collections (local requests only) | C35: 194 | D35: 111 | F35: 83 | G35: 7 | H35: 2 | J35: 5 | K35: 1
A36: Atchison Public Library | B36: Special collections (no requests allowed) | C36: 7 | D36: 5 | E36: 1 | F36: 1
A37: Atchison Public Library | B37: Story walk
A38: Atchison Public Library | B38: Things - Artwork
A39: Atchison Public Library | B39: Things - Audio-visual equipment
A40: Atchison Public Library | B40: Things - Bicycles (and bicycle accessories)
...

Sheet March
A1: branchname | B1: ITEM TYPE | C1: TOTAL ITEMS | D1: ADULT ITEMS | E1: YOUNG ADULT ITEMS | F1: JUVENILE ITEMS | G1: TOTAL ADDED LM | H1: ADULT ADDED LM | I1: YOUNG ADULT ADDED LM | J1: JUVENILE ADDED LM | K1: TOTAL DELETED LM | L1: ADULT DELETED LM | M1: YOUNG ADULT DELETED LM | N1: JUVENILE DELETED LM
A2: Atchison Public Library | B2: (Unclassified)
A3: Atchison Public Library | B3: Audiobook (CDs or cassettes) | C3: 2541 | D3: 2479 | E3: 2 | F3: 60
A4: Atchison Public Library | B4: Audiobook (digital media)
A5: Atchison Public Library | B5: Audiobook (new) | C5: 35 | D5: 35 | G5: 1 | H5: 1
A6: Atchison Public Library | B6: Audiobook (preloaded player) | C6: 7 | D6: 7
A7: Atchison Public Library | B7: Book | C7: 51735 | D7: 32159 | E7: 4997 | F7: 14579 | G7: 19 | H7: 13 | I7: 2 | J7: 4 | K7: 16
A8: Atchison Public Library | B8: Book - School District 454
A9: Atchison Public Library | B9: Book (local requests only)
A10: Atchison Public Library | B10: Book (new) | C10: 961 | D10: 655 | E10: 87 | F10: 219 | G10: 252 | H10: 197 | I10: 23 | J10: 32 | K10: 1
A11: Atchison Public Library | B11: Book (no requests allowed)
A12: Atchison Public Library | B12: Book club set
A13: Atchison Public Library | B13: Bundle
A14: Atchison Public Library | B14: Computers and internet - Laptop computer
A15: Atchison Public Library | B15: Computers and internet - Launchpad tablet | C15: 1 | F15: 1
A16: Atchison Public Library | B16: Computers and internet - Public computer
A17: Atchison Public Library | B17: Computers and internet - Software
A18: Atchison Public Library | B18: Computers and internet - Tablets, e-readers, and personal computing devices
A19: Atchison Public Library | B19: Computers and internet - Wireless internet hotspot
A20: Atchison Public Library | B20: E-content - Digital content
A21: Atchison Public Library | B21: Inter-library loan | C21: 50 | D21: 45 | F21: 5 | G21: 15 | H21: 15 | K21: 29 | L21: 10
A22: Atchison Public Library | B22: Inter-library loan - 07 day loan
A23: Atchison Public Library | B23: Inter-library loan - 14 day loan
A24: Atchison Public Library | B24: Inter-library loan - 21 day loan
A25: Atchison Public Library | B25: Inter-library loan - 28 day loan
A26: Atchison Public Library | B26: Key
A27: Atchison Public Library | B27: Kit or multi-part set | C27: 24 | D27: 5 | E27: 1 | F27: 18
A28: Atchison Public Library | B28: Magazine
A29: Atchison Public Library | B29: Magazine (new)
A30: Atchison Public Library | B30: Music | C30: 3 | D30: 3
A31: Atchison Public Library | B31: Pamphlet
A32: Atchison Public Library | B32: Reference material | C32: 1131 | D32: 1129 | F32: 2 | G32: 5 | H32: 5
A33: Atchison Public Library | B33: Reserve desk - Highland Community College
A34: Atchison Public Library | B34: Room
A35: Atchison Public Library | B35: Special collections (local requests only) | C35: 225 | D35: 140 | F35: 85 | G35: 9 | H35: 9 | K35: 1
A36: Atchison Public Library | B36: Special collections (no requests allowed) | C36: 6 | D36: 4 | E36: 1 | F36: 1
A37: Atchison Public Library | B37: Story walk
A38: Atchison Public Library | B38: Things - Artwork
A39: Atchison Public Library | B39: Things - Audio-visual equipment
A40: Atchison Public Library | B40: Things - Bicycles (and bicycle accessories)
...

Sheet April
A1: branchname | B1: ITEM TYPE | C1: TOTAL ITEMS | D1: ADULT ITEMS | E1: YOUNG ADULT ITEMS | F1: JUVENILE ITEMS | G1: TOTAL ADDED LM | H1: ADULT ADDED LM | I1: YOUNG ADULT ADDED LM | J1: JUVENILE ADDED LM | K1: TOTAL DELETED LM | L1: ADULT DELETED LM | M1: YOUNG ADULT DELETED LM | N1: JUVENILE DELETED LM
A2: Atchison Public Library | B2: (Unclassified)
A3: Atchison Public Library | B3: Audiobook (CDs or cassettes) | C3: 2546 | D3: 2484 | E3: 2 | F3: 60 | G3: 5 | H3: 5
A4: Atchison Public Library | B4: Audiobook (digital media)
A5: Atchison Public Library | B5: Audiobook (new) | C5: 36 | D5: 36 | G5: 1 | H5: 1
A6: Atchison Public Library | B6: Audiobook (preloaded player) | C6: 7 | D6: 7
A7: Atchison Public Library | B7: Book | C7: 51846 | D7: 32224 | E7: 4999 | F7: 14623 | G7: 18 | H7: 12 | I7: 2 | J7: 4 | K7: 58
A8: Atchison Public Library | B8: Book - School District 454
A9: Atchison Public Library | B9: Book (local requests only)
A10: Atchison Public Library | B10: Book (new) | C10: 1056 | D10: 733 | E10: 127 | F10: 196 | G10: 248 | H10: 179 | I10: 43 | J10: 26 | K10: 3 | L10: 1
A11: Atchison Public Library | B11: Book (no requests allowed)
A12: Atchison Public Library | B12: Book club set
A13: Atchison Public Library | B13: Bundle
A14: Atchison Public Library | B14: Computers and internet - Laptop computer
A15: Atchison Public Library | B15: Computers and internet - Launchpad tablet | C15: 1 | F15: 1
A16: Atchison Public Library | B16: Computers and internet - Public computer
A17: Atchison Public Library | B17: Computers and internet - Software
A18: Atchison Public Library | B18: Computers and internet - Tablets, e-readers, and personal computing devices
A19: Atchison Public Library | B19: Computers and internet - Wireless internet hotspot
A20: Atchison Public Library | B20: E-content - Digital content
A21: Atchison Public Library | B21: Inter-library loan | C21: 45 | D21: 40 | F21: 5 | G21: 8 | H21: 8 | K21: 19 | L21: 6
A22: Atchison Public Library | B22: Inter-library loan - 07 day loan
A23: Atchison Public Library | B23: Inter-library loan - 14 day loan
A24: Atchison Public Library | B24: Inter-library loan - 21 day loan
A25: Atchison Public Library | B25: Inter-library loan - 28 day loan
A26: Atchison Public Library | B26: Key
A27: Atchison Public Library | B27: Kit or multi-part set | C27: 23 | D27: 4 | E27: 1 | F27: 18 | K27: 1
A28: Atchison Public Library | B28: Magazine
A29: Atchison Public Library | B29: Magazine (new)
A30: Atchison Public Library | B30: Music | C30: 3 | D30: 3
A31: Atchison Public Library | B31: Pamphlet
A32: Atchison Public Library | B32: Reference material | C32: 1131 | D32: 1129 | F32: 2
A33: Atchison Public Library | B33: Reserve desk - Highland Community College
A34: Atchison Public Library | B34: Room
A35: Atchison Public Library | B35: Special collections (local requests only) | C35: 230 | D35: 143 | F35: 87 | G35: 5 | H35: 4 | J35: 1 | K35: 1
A36: Atchison Public Library | B36: Special collections (no requests allowed) | C36: 6 | D36: 4 | E36: 1 | F36: 1
A37: Atchison Public Library | B37: Story walk
A38: Atchison Public Library | B38: Things - Artwork
A39: Atchison Public Library | B39: Things - Audio-visual equipment
A40: Atchison Public Library | B40: Things - Bicycles (and bicycle accessories)
...

Sheet May
A1: branchname | B1: ITEM TYPE | C1: TOTAL ITEMS | D1: ADULT ITEMS | E1: YOUNG ADULT ITEMS | F1: JUVENILE ITEMS | G1: TOTAL ADDED LM | H1: ADULT ADDED LM | I1: YOUNG ADULT ADDED LM | J1: JUVENILE ADDED LM | K1: TOTAL DELETED LM | L1: ADULT DELETED LM | M1: YOUNG ADULT DELETED LM | N1: JUVENILE DELETED LM
A2: Atchison Public Library | B2: (Unclassified)
A3: Atchison Public Library | B3: Audiobook (CDs or cassettes) | C3: 2548 | D3: 2484 | E3: 2 | F3: 62 | G3: 2 | J3: 2
A4: Atchison Public Library | B4: Audiobook (digital media)
A5: Atchison Public Library | B5: Audiobook (new) | C5: 36 | D5: 36
A6: Atchison Public Library | B6: Audiobook (preloaded player) | C6: 7 | D6: 7
A7: Atchison Public Library | B7: Book | C7: 52042 | D7: 32365 | E7: 5046 | F7: 14631 | G7: 13 | H7: 2 | I7: 9 | J7: 2 | K7: 46
A8: Atchison Public Library | B8: Book - School District 454
A9: Atchison Public Library | B9: Book (local requests only)
A10: Atchison Public Library | B10: Book (new) | C10: 1025 | D10: 686 | E10: 106 | F10: 233 | G10: 198 | H10: 118 | I10: 23 | J10: 57 | K10: 2
A11: Atchison Public Library | B11: Book (no requests allowed)
A12: Atchison Public Library | B12: Book club set
A13: Atchison Public Library | B13: Bundle
A14: Atchison Public Library | B14: Computers and internet - Laptop computer
A15: Atchison Public Library | B15: Computers and internet - Launchpad tablet | C15: 1 | F15: 1
A16: Atchison Public Library | B16: Computers and internet - Public computer
A17: Atchison Public Library | B17: Computers and internet - Software
A18: Atchison Public Library | B18: Computers and internet - Tablets, e-readers, and personal computing devices
A19: Atchison Public Library | B19: Computers and internet - Wireless internet hotspot
A20: Atchison Public Library | B20: E-content - Digital content
A21: Atchison Public Library | B21: Inter-library loan | C21: 49 | D21: 44 | F21: 5 | G21: 10 | H21: 10 | K21: 15 | L21: 9
A22: Atchison Public Library | B22: Inter-library loan - 07 day loan
A23: Atchison Public Library | B23: Inter-library loan - 14 day loan
A24: Atchison Public Library | B24: Inter-library loan - 21 day loan
A25: Atchison Public Library | B25: Inter-library loan - 28 day loan
A26: Atchison Public Library | B26: Key
A27: Atchison Public Library | B27: Kit or multi-part set | C27: 20 | D27: 1 | E27: 1 | F27: 18 | K27: 3
A28: Atchison Public Library | B28: Magazine
A29: Atchison Public Library | B29: Magazine (new)
A30: Atchison Public Library | B30: Music | C30: 3 | D30: 3
A31: Atchison Public Library | B31: Pamphlet
A32: Atchison Public Library | B32: Reference material | C32: 1131 | D32: 1129 | F32: 2
A33: Atchison Public Library | B33: Reserve desk - Highland Community College
A34: Atchison Public Library | B34: Room
A35: Atchison Public Library | B35: Special collections (local requests only) | C35: 231 | D35: 144 | F35: 87 | G35: 1 | H35: 1
A36: Atchison Public Library | B36: Special collections (no requests allowed) | C36: 6 | D36: 4 | E36: 1 | F36: 1
A37: Atchison Public Library | B37: Story walk
A38: Atchison Public Library | B38: Things - Artwork
A39: Atchison Public Library | B39: Things - Audio-visual equipment
A40: Atchison Public Library | B40: Things - Bicycles (and bicycle accessories)
...

Sheet June
A1: branchname | B1: ITEM TYPE | C1: TOTAL ITEMS | D1: ADULT ITEMS | E1: YOUNG ADULT ITEMS | F1: JUVENILE ITEMS | G1: TOTAL ADDED LM | H1: ADULT ADDED LM | I1: YOUNG ADULT ADDED LM | J1: JUVENILE ADDED LM | K1: TOTAL DELETED LM | L1: ADULT DELETED LM | M1: YOUNG ADULT DELETED LM | N1: JUVENILE DELETED LM
A2: Atchison Public Library | B2: (Unclassified)
A3: Atchison Public Library | B3: Audiobook (CDs or cassettes) | C3: 2554 | D3: 2490 | E3: 2 | F3: 62
A4: Atchison Public Library | B4: Audiobook (digital media)
A5: Atchison Public Library | B5: Audiobook (new) | C5: 34 | D5: 34 | G5: 4 | H5: 4
A6: Atchison Public Library | B6: Audiobook (preloaded player) | C6: 7 | D6: 7
A7: Atchison Public Library | B7: Book | C7: 52246 | D7: 32520 | E7: 5076 | F7: 14650 | G7: 6 | H7: 3 | I7: 2 | J7: 1 | K7: 50
A8: Atchison Public Library | B8: Book - School District 454
A9: Atchison Public Library | B9: Book (local requests only)
A10: Atchison Public Library | B10: Book (new) | C10: 1011 | D10: 650 | E10: 113 | F10: 248 | G10: 233 | H10: 143 | I10: 39 | J10: 51 | K10: 1 | N10: 1
A11: Atchison Public Library | B11: Book (no requests allowed)
A12: Atchison Public Library | B12: Book club set
A13: Atchison Public Library | B13: Bundle
A14: Atchison Public Library | B14: Computers and internet - Laptop computer
A15: Atchison Public Library | B15: Computers and internet - Launchpad tablet | C15: 1 | F15: 1
A16: Atchison Public Library | B16: Computers and internet - Public computer
A17: Atchison Public Library | B17: Computers and internet - Software
A18: Atchison Public Library | B18: Computers and internet - Tablets, e-readers, and personal computing devices
A19: Atchison Public Library | B19: Computers and internet - Wireless internet hotspot
A20: Atchison Public Library | B20: E-content - Digital content
A21: Atchison Public Library | B21: Inter-library loan | C21: 53 | D21: 48 | F21: 5 | G21: 15 | H21: 15 | K21: 17 | L21: 6
A22: Atchison Public Library | B22: Inter-library loan - 07 day loan
A23: Atchison Public Library | B23: Inter-library loan - 14 day loan
A24: Atchison Public Library | B24: Inter-library loan - 21 day loan
A25: Atchison Public Library | B25: Inter-library loan - 28 day loan
A26: Atchison Public Library | B26: Key
A27: Atchison Public Library | B27: Kit or multi-part set | C27: 20 | D27: 1 | E27: 1 | F27: 18
A28: Atchison Public Library | B28: Magazine
A29: Atchison Public Library | B29: Magazine (new)
A30: Atchison Public Library | B30: Music | C30: 3 | D30: 3
A31: Atchison Public Library | B31: Pamphlet
A32: Atchison Public Library | B32: Reference material | C32: 1131 | D32: 1129 | F32: 2
A33: Atchison Public Library | B33: Reserve desk - Highland Community College
A34: Atchison Public Library | B34: Room
A35: Atchison Public Library | B35: Special collections (local requests only) | C35: 232 | D35: 145 | F35: 87 | G35: 3 | H35: 3 | K35: 2
A36: Atchison Public Library | B36: Special collections (no requests allowed) | C36: 6 | D36: 4 | E36: 1 | F36: 1
A37: Atchison Public Library | B37: Story walk
A38: Atchison Public Library | B38: Things - Artwork
A39: Atchison Public Library | B39: Things - Audio-visual equipment
A40: Atchison Public Library | B40: Things - Bicycles (and bicycle accessories)
...

Sheet July
A1: branchname | B1: ITEM TYPE | C1: TOTAL ITEMS | D1: ADULT ITEMS | E1: YOUNG ADULT ITEMS | F1: JUVENILE ITEMS | G1: TOTAL ADDED LM | H1: ADULT ADDED LM | I1: YOUNG ADULT ADDED LM | J1: JUVENILE ADDED LM | K1: TOTAL DELETED LM | L1: ADULT DELETED LM | M1: YOUNG ADULT DELETED LM | N1: JUVENILE DELETED LM
A2: Atchison Public Library | B2: (Unclassified)
A3: Atchison Public Library | B3: Audiobook (CDs or cassettes) | C3: 2552 | D3: 2490 | E3: 2 | F3: 60
A4: Atchison Public Library | B4: Audiobook (digital media)
A5: Atchison Public Library | B5: Audiobook (new) | C5: 34 | D5: 34
A6: Atchison Public Library | B6: Audiobook (preloaded player) | C6: 7 | D6: 7
A7: Atchison Public Library | B7: Book | C7: 52325 | D7: 32523 | E7: 5111 | F7: 14691 | G7: 30 | H7: 9 | I7: 7 | J7: 14 | K7: 368
A8: Atchison Public Library | B8: Book - School District 454
A9: Atchison Public Library | B9: Book (local requests only)
A10: Atchison Public Library | B10: Book (new) | C10: 1070 | D10: 593 | E10: 160 | F10: 317 | G10: 477 | H10: 270 | I10: 81 | J10: 126 | K10: 12
A11: Atchison Public Library | B11: Book (no requests allowed)
A12: Atchison Public Library | B12: Book club set
A13: Atchison Public Library | B13: Bundle
A14: Atchison Public Library | B14: Computers and internet - Laptop computer
A15: Atchison Public Library | B15: Computers and internet - Launchpad tablet | C15: 1 | F15: 1
A16: Atchison Public Library | B16: Computers and internet - Public computer
A17: Atchison Public Library | B17: Computers and internet - Software
A18: Atchison Public Library | B18: Computers and internet - Tablets, e-readers, and personal computing devices
A19: Atchison Public Library | B19: Computers and internet - Wireless internet hotspot
A20: Atchison Public Library | B20: E-content - Digital content
A21: Atchison Public Library | B21: Inter-library loan | C21: 50 | D21: 45 | F21: 5 | G21: 19 | H21: 19 | K21: 34 | L21: 12
A22: Atchison Public Library | B22: Inter-library loan - 07 day loan
A23: Atchison Public Library | B23: Inter-library loan - 14 day loan
A24: Atchison Public Library | B24: Inter-library loan - 21 day loan
A25: Atchison Public Library | B25: Inter-library loan - 28 day loan
A26: Atchison Public Library | B26: Key
A27: Atchison Public Library | B27: Kit or multi-part set | C27: 19 | D27: 1 | E27: 1 | F27: 17
A28: Atchison Public Library | B28: Magazine
A29: Atchison Public Library | B29: Magazine (new)
A30: Atchison Public Library | B30: Music | C30: 3 | D30: 3
A31: Atchison Public Library | B31: Pamphlet
A32: Atchison Public Library | B32: Reference material | C32: 1136 | D32: 1134 | F32: 2 | G32: 5 | H32: 5
A33: Atchison Public Library | B33: Reserve desk - Highland Community College
A34: Atchison Public Library | B34: Room
A35: Atchison Public Library | B35: Special collections (local requests only) | C35: 239 | D35: 144 | F35: 95 | G35: 3 | H35: 3
A36: Atchison Public Library | B36: Special collections (no requests allowed) | C36: 6 | D36: 4 | E36: 1 | F36: 1
A37: Atchison Public Library | B37: Story walk
A38: Atchison Public Library | B38: Things - Artwork
A39: Atchison Public Library | B39: Things - Audio-visual equipment
A40: Atchison Public Library | B40: Things - Bicycles (and bicycle accessories)
...

Sheet August
A1: branchname | B1: ITEM TYPE | C1: TOTAL ITEMS | D1: ADULT ITEMS | E1: YOUNG ADULT ITEMS | F1: JUVENILE ITEMS | G1: TOTAL ADDED LM | H1: ADULT ADDED LM | I1: YOUNG ADULT ADDED LM | J1: JUVENILE ADDED LM | K1: TOTAL DELETED LM | L1: ADULT DELETED LM | M1: YOUNG ADULT DELETED LM | N1: JUVENILE DELETED LM
A2: Atchison Public Library | B2: (Unclassified)
A3: Atchison Public Library | B3: Audiobook (CDs or cassettes) | C3: 2552 | D3: 2492 | E3: 2 | F3: 58 | G3: 2 | H3: 2
A4: Atchison Public Library | B4: Audiobook (digital media)
A5: Atchison Public Library | B5: Audiobook (new) | C5: 35 | D5: 35 | G5: 1 | H5: 1
A6: Atchison Public Library | B6: Audiobook (preloaded player) | C6: 7 | D6: 7
A7: Atchison Public Library | B7: Book | C7: 52458 | D7: 32616 | E7: 5085 | F7: 14757 | G7: 37 | H7: 21 | I7: 15 | J7: 1 | K7: 117
A8: Atchison Public Library | B8: Book - School District 454
A9: Atchison Public Library | B9: Book (local requests only)
A10: Atchison Public Library | B10: Book (new) | C10: 1045 | D10: 633 | E10: 139 | F10: 273 | G10: 191 | H10: 145 | I10: 17 | J10: 29 | K10: 3
A11: Atchison Public Library | B11: Book (no requests allowed)
A12: Atchison Public Library | B12: Book club set
A13: Atchison Public Library | B13: Bundle
A14: Atchison Public Library | B14: Computers and internet - Laptop computer
A15: Atchison Public Library | B15: Computers and internet - Launchpad tablet | C15: 1 | F15: 1
A16: Atchison Public Library | B16: Computers and internet - Public computer
A17: Atchison Public Library | B17: Computers and internet - Software
A18: Atchison Public Library | B18: Computers and internet - Tablets, e-readers, and personal computing devices
A19: Atchison Public Library | B19: Computers and internet - Wireless internet hotspot
A20: Atchison Public Library | B20: E-content - Digital content
A21: Atchison Public Library | B21: Inter-library loan | C21: 45 | D21: 40 | F21: 5 | G21: 9 | H21: 9 | K21: 18 | L21: 4
A22: Atchison Public Library | B22: Inter-library loan - 07 day loan
A23: Atchison Public Library | B23: Inter-library loan - 14 day loan
A24: Atchison Public Library | B24: Inter-library loan - 21 day loan
A25: Atchison Public Library | B25: Inter-library loan - 28 day loan
A26: Atchison Public Library | B26: Key
A27: Atchison Public Library | B27: Kit or multi-part set | C27: 20 | D27: 1 | E27: 1 | F27: 18 | G27: 1 | J27: 1
A28: Atchison Public Library | B28: Magazine
A29: Atchison Public Library | B29: Magazine (new)
A30: Atchison Public Library | B30: Music | C30: 3 | D30: 3
A31: Atchison Public Library | B31: Pamphlet
A32: Atchison Public Library | B32: Reference material | C32: 1136 | D32: 1134 | F32: 2
A33: Atchison Public Library | B33: Reserve desk - Highland Community College
A34: Atchison Public Library | B34: Room
A35: Atchison Public Library | B35: Special collections (local requests only) | C35: 243 | D35: 145 | F35: 98 | G35: 4 | H35: 1 | J35: 3 | K35: 2
A36: Atchison Public Library | B36: Special collections (no requests allowed) | C36: 6 | D36: 4 | E36: 1 | F36: 1
A37: Atchison Public Library | B37: Story walk
A38: Atchison Public Library | B38: Things - Artwork
A39: Atchison Public Library | B39: Things - Audio-visual equipment
A40: Atchison Public Library | B40: Things - Bicycles (and bicycle accessories)
...

Sheet September
A1: branchname | B1: ITEM TYPE | C1: TOTAL ITEMS | D1: ADULT ITEMS | E1: YOUNG ADULT ITEMS | F1: JUVENILE ITEMS | G1: TOTAL ADDED LM | H1: ADULT ADDED LM | I1: YOUNG ADULT ADDED LM | J1: JUVENILE ADDED LM | K1: TOTAL DELETED LM | L1: ADULT DELETED LM | M1: YOUNG ADULT DELETED LM | N1: JUVENILE DELETED LM
A2: Atchison Public Library | B2: (Unclassified)
A3: Atchison Public Library | B3: Audiobook (CDs or cassettes) | C3: 2555 | D3: 2495 | E3: 2 | F3: 58
A4: Atchison Public Library | B4: Audiobook (digital media)
A5: Atchison Public Library | B5: Audiobook (new) | C5: 35 | D5: 35 | G5: 3 | H5: 3
A6: Atchison Public Library | B6: Audiobook (preloaded player) | C6: 7 | D6: 7
A7: Atchison Public Library | B7: Book | C7: 52475 | D7: 32670 | E7: 5062 | F7: 14743 | G7: 13 | H7: 12 | I7: 1 | K7: 205
A8: Atchison Public Library | B8: Book - School District 454
A9: Atchison Public Library | B9: Book (local requests only)
A10: Atchison Public Library | B10: Book (new) | C10: 1118 | D10: 655 | E10: 154 | F10: 309 | G10: 284 | H10: 161 | I10: 17 | J10: 106 | K10: 5 | M10: 1
A11: Atchison Public Library | B11: Book (no requests allowed)
A12: Atchison Public Library | B12: Book club set
A13: Atchison Public Library | B13: Bundle
A14: Atchison Public Library | B14: Computers and internet - Laptop computer
A15: Atchison Public Library | B15: Computers and internet - Launchpad tablet | C15: 1 | F15: 1
A16: Atchison Public Library | B16: Computers and internet - Public computer
A17: Atchison Public Library | B17: Computers and internet - Software
A18: Atchison Public Library | B18: Computers and internet - Tablets, e-readers, and personal computing devices
A19: Atchison Public Library | B19: Computers and internet - Wireless internet hotspot
A20: Atchison Public Library | B20: E-content - Digital content
A21: Atchison Public Library | B21: Inter-library loan | C21: 53 | D21: 48 | F21: 5 | G21: 14 | H21: 14 | K21: 14 | L21: 8
A22: Atchison Public Library | B22: Inter-library loan - 07 day loan
A23: Atchison Public Library | B23: Inter-library loan - 14 day loan
A24: Atchison Public Library | B24: Inter-library loan - 21 day loan
A25: Atchison Public Library | B25: Inter-library loan - 28 day loan
A26: Atchison Public Library | B26: Key
A27: Atchison Public Library | B27: Kit or multi-part set | C27: 20 | D27: 1 | E27: 1 | F27: 18
A28: Atchison Public Library | B28: Magazine
A29: Atchison Public Library | B29: Magazine (new)
A30: Atchison Public Library | B30: Music | C30: 3 | D30: 3
A31: Atchison Public Library | B31: Pamphlet
A32: Atchison Public Library | B32: Reference material | C32: 1137 | D32: 1135 | F32: 2 | G32: 1 | H32: 1
A33: Atchison Public Library | B33: Reserve desk - Highland Community College
A34: Atchison Public Library | B34: Room
A35: Atchison Public Library | B35: Special collections (local requests only) | C35: 242 | D35: 144 | F35: 98 | K35: 1
A36: Atchison Public Library | B36: Special collections (no requests allowed) | C36: 6 | D36: 4 | E36: 1 | F36: 1
A37: Atchison Public Library | B37: Story walk
A38: Atchison Public Library | B38: Things - Artwork
A39: Atchison Public Library | B39: Things - Audio-visual equipment
A40: Atchison Public Library | B40: Things - Bicycles (and bicycle accessories)
...

Sheet October
A1: branchname | B1: ITEM TYPE | C1: TOTAL ITEMS | D1: ADULT ITEMS | E1: YOUNG ADULT ITEMS | F1: JUVENILE ITEMS | G1: TOTAL ADDED LM | H1: ADULT ADDED LM | I1: YOUNG ADULT ADDED LM | J1: JUVENILE ADDED LM | K1: TOTAL DELETED LM | L1: ADULT DELETED LM | M1: YOUNG ADULT DELETED LM | N1: JUVENILE DELETED LM
A2: Atchison Public Library | B2: (Unclassified)
A3: Atchison Public Library | B3: Audiobook (CDs or cassettes)
A4: Atchison Public Library | B4: Audiobook (digital media)
A5: Atchison Public Library | B5: Audiobook (new)
A6: Atchison Public Library | B6: Audiobook (preloaded player)
A7: Atchison Public Library | B7: Book
A8: Atchison Public Library | B8: Book - School District 454
A9: Atchison Public Library | B9: Book (local requests only)
A10: Atchison Public Library | B10: Book (new)
A11: Atchison Public Library | B11: Book (no requests allowed)
A12: Atchison Public Library | B12: Book club set
A13: Atchison Public Library | B13: Bundle
... A2916: Winchester Public Library | B2916: Video game
A2917: Doniphan County Total | B2917: (Unclassified) | C2917: =SUM(C552,C607,C662,C717) -> 0 | D2917: =SUM(D552,D607,D662,D717) -> 0 | E2917: =SUM(E552,E607,E662,E717) -> 0 | F2917: =SUM(F552,F607,F662,F717) -> 0 | G2917: =SUM(G552,G607,G662,G717) -> 0 | H2917: =SUM(H552,H607,H662,H717) -> 0 | I2917: =SUM(I552,I607,I662,I717) -> 0 | J2917: =SUM(J552,J607,J662,J717) -> 0 | ... N2917: =SUM(N552,N607,N662,N717) -> 0
A2918: Doniphan County Total | B2918: Audiobook (CDs or cassettes) | C2918: =SUM(C553,C608,C663,C718) -> 0 | D2918: =SUM(D553,D608,D663,D718) -> 0 | E2918: =SUM(E553,E608,E663,E718) -> 0 | F2918: =SUM(F553,F608,F663,F718) -> 0 | G2918: =SUM(G553,G608,G663,G718) -> 0 | H2918: =SUM(H553,H608,H663,H718) -> 0 | I2918: =SUM(I553,I608,I663,I718) -> 0 | J2918: =SUM(J553,J608,J663,J718) -> 0 | ... N2918: =SUM(N553,N608,N663,N718) -> 0
A2919: Doniphan County Total | B2919: Audiobook (digital media) | C2919: =SUM(C554,C609,C664,C719) -> 0 | D2919: =SUM(D554,D609,D664,D719) -> 0 | E2919: =SUM(E554,E609,E664,E719) -> 0 | F2919: =SUM(F554,F609,F664,F719) -> 0 | G2919: =SUM(G554,G609,G664,G719) -> 0 | H2919: =SUM(H554,H609,H664,H719) -> 0 | I2919: =SUM(I554,I609,I664,I719) -> 0 | J2919: =SUM(J554,J609,J664,J719) -> 0 | ... N2919: =SUM(N554,N609,N664,N719) -> 0
A2920: Doniphan County Total | B2920: Audiobook (new) | C2920: =SUM(C555,C610,C665,C720) -> 0 | D2920: =SUM(D555,D610,D665,D720) -> 0 | E2920: =SUM(E555,E610,E665,E720) -> 0 | F2920: =SUM(F555,F610,F665,F720) -> 0 | G2920: =SUM(G555,G610,G665,G720) -> 0 | H2920: =SUM(H555,H610,H665,H720) -> 0 | I2920: =SUM(I555,I610,I665,I720) -> 0 | J2920: =SUM(J555,J610,J665,J720) -> 0 | ... N2920: =SUM(N555,N610,N665,N720) -> 0
A2921: Doniphan County Total | B2921: Audiobook (preloaded player) | C2921: =SUM(C556,C611,C666,C721) -> 0 | D2921: =SUM(D556,D611,D666,D721) -> 0 | E2921: =SUM(E556,E611,E666,E721) -> 0 | F2921: =SUM(F556,F611,F666,F721) -> 0 | G2921: =SUM(G556,G611,G666,G721) -> 0 | H2921: =SUM(H556,H611,H666,H721) -> 0 | I2921: =SUM(I556,I611,I666,I721) -> 0 | J2921: =SUM(J556,J611,J666,J721) -> 0 | ... N2921: =SUM(N556,N611,N666,N721) -> 0
A2922: Doniphan County Total | B2922: Book | C2922: =SUM(C557,C612,C667,C722) -> 0 | D2922: =SUM(D557,D612,D667,D722) -> 0 | E2922: =SUM(E557,E612,E667,E722) -> 0 | F2922: =SUM(F557,F612,F667,F722) -> 0 | G2922: =SUM(G557,G612,G667,G722) -> 0 | H2922: =SUM(H557,H612,H667,H722) -> 0 | I2922: =SUM(I557,I612,I667,I722) -> 0 | J2922: =SUM(J557,J612,J667,J722) -> 0 | ... N2922: =SUM(N557,N612,N667,N722) -> 0
A2923: Doniphan County Total | B2923: Book - School District 454 | C2923: =SUM(C558,C613,C668,C723) -> 0 | D2923: =SUM(D558,D613,D668,D723) -> 0 | E2923: =SUM(E558,E613,E668,E723) -> 0 | F2923: =SUM(F558,F613,F668,F723) -> 0 | G2923: =SUM(G558,G613,G668,G723) -> 0 | H2923: =SUM(H558,H613,H668,H723) -> 0 | I2923: =SUM(I558,I613,I668,I723) -> 0 | J2923: =SUM(J558,J613,J668,J723) -> 0 | ... N2923: =SUM(N558,N613,N668,N723) -> 0
A2924: Doniphan County Total | B2924: Book (local requests only) | C2924: =SUM(C559,C614,C669,C724) -> 0 | D2924: =SUM(D559,D614,D669,D724) -> 0 | E2924: =SUM(E559,E614,E669,E724) -> 0 | F2924: =SUM(F559,F614,F669,F724) -> 0 | G2924: =SUM(G559,G614,G669,G724) -> 0 | H2924: =SUM(H559,H614,H669,H724) -> 0 | I2924: =SUM(I559,I614,I669,I724) -> 0 | J2924: =SUM(J559,J614,J669,J724) -> 0 | ... N2924: =SUM(N559,N614,N669,N724) -> 0
A2925: Doniphan County Total | B2925: Book (new) | C2925: =SUM(C560,C615,C670,C725) -> 0 | D2925: =SUM(D560,D615,D670,D725) -> 0 | E2925: =SUM(E560,E615,E670,E725) -> 0 | F2925: =SUM(F560,F615,F670,F725) -> 0 | G2925: =SUM(G560,G615,G670,G725) -> 0 | H2925: =SUM(H560,H615,H670,H725) -> 0 | I2925: =SUM(I560,I615,I670,I725) -> 0 | J2925: =SUM(J560,J615,J670,J725) -> 0 | ... N2925: =SUM(N560,N615,N670,N725) -> 0
A2926: Doniphan County Total | B2926: Book (no requests allowed) | C2926: =SUM(C561,C616,C671,C726) -> 0 | D2926: =SUM(D561,D616,D671,D726) -> 0 | E2926: =SUM(E561,E616,E671,E726) -> 0 | F2926: =SUM(F561,F616,F671,F726) -> 0 | G2926: =SUM(G561,G616,G671,G726) -> 0 | H2926: =SUM(H561,H616,H671,H726) -> 0 | I2926: =SUM(I561,I616,I671,I726) -> 0 | J2926: =SUM(J561,J616,J671,J726) -> 0 | ... N2926: =SUM(N561,N616,N671,N726) -> 0
A2927: Doniphan County Total | B2927: Book club set | C2927: =SUM(C562,C617,C672,C727) -> 0 | D2927: =SUM(D562,D617,D672,D727) -> 0 | E2927: =SUM(E562,E617,E672,E727) -> 0 | F2927: =SUM(F562,F617,F672,F727) -> 0 | G2927: =SUM(G562,G617,G672,G727) -> 0 | H2927: =SUM(H562,H617,H672,H727) -> 0 | I2927: =SUM(I562,I617,I672,I727) -> 0 | J2927: =SUM(J562,J617,J672,J727) -> 0 | ... N2927: =SUM(N562,N617,N672,N727) -> 0
A2928: Doniphan County Total | B2928: Bundle | C2928: =SUM(C563,C618,C673,C728) -> 0 | D2928: =SUM(D563,D618,D673,D728) -> 0 | E2928: =SUM(E563,E618,E673,E728) -> 0 | F2928: =SUM(F563,F618,F673,F728) -> 0 | G2928: =SUM(G563,G618,G673,G728) -> 0 | H2928: =SUM(H563,H618,H673,H728) -> 0 | I2928: =SUM(I563,I618,I673,I728) -> 0 | J2928: =SUM(J563,J618,J673,J728) -> 0 | ... N2928: =SUM(N563,N618,N673,N728) -> 0
... A2971: Doniphan County Total | B2971: Video game | C2971: =SUM(C606,C661,C716,C771) -> 0 | D2971: =SUM(D606,D661,D716,D771) -> 0 | E2971: =SUM(E606,E661,E716,E771) -> 0 | F2971: =SUM(F606,F661,F716,F771) -> 0 | G2971: =SUM(G606,G661,G716,G771) -> 0 | H2971: =SUM(H606,H661,H716,H771) -> 0 | I2971: =SUM(I606,I661,I716,I771) -> 0 | J2971: =SUM(J606,J661,J716,J771) -> 0 | ... N2971: =SUM(N606,N661,N716,N771) -> 0
A2972: Prairie Hills Schools Total | B2972: (Unclassified) | C2972: =SUM(C2092,C2147,C2202,C2257) -> 0 | D2972: =SUM(D2092,D2147,D2202,D2257) -> 0 | E2972: =SUM(E2092,E2147,E2202,E2257) -> 0 | F2972: =SUM(F2092,F2147,F2202,F2257) -> 0 | G2972: =SUM(G2092,G2147,G2202,G2257) -> 0 | H2972: =SUM(H2092,H2147,H2202,H2257) -> 0 | I2972: =SUM(I2092,I2147,I2202,I2257) -> 0 | J2972: =SUM(J2092,J2147,J2202,J2257) -> 0 | ... N2972: =SUM(N2092,N2147,N2202,N2257) -> 0
A2973: Prairie Hills Schools Total | B2973: Audiobook (CDs or cassettes) | C2973: =SUM(C2093,C2148,C2203,C2258) -> 0 | D2973: =SUM(D2093,D2148,D2203,D2258) -> 0 | E2973: =SUM(E2093,E2148,E2203,E2258) -> 0 | F2973: =SUM(F2093,F2148,F2203,F2258) -> 0 | G2973: =SUM(G2093,G2148,G2203,G2258) -> 0 | H2973: =SUM(H2093,H2148,H2203,H2258) -> 0 | I2973: =SUM(I2093,I2148,I2203,I2258) -> 0 | J2973: =SUM(J2093,J2148,J2203,J2258) -> 0 | ... N2973: =SUM(N2093,N2148,N2203,N2258) -> 0
A2974: Prairie Hills Schools Total | B2974: Audiobook (digital media) | C2974: =SUM(C2094,C2149,C2204,C2259) -> 0 | D2974: =SUM(D2094,D2149,D2204,D2259) -> 0 | E2974: =SUM(E2094,E2149,E2204,E2259) -> 0 | F2974: =SUM(F2094,F2149,F2204,F2259) -> 0 | G2974: =SUM(G2094,G2149,G2204,G2259) -> 0 | H2974: =SUM(H2094,H2149,H2204,H2259) -> 0 | I2974: =SUM(I2094,I2149,I2204,I2259) -> 0 | J2974: =SUM(J2094,J2149,J2204,J2259) -> 0 | ... N2974: =SUM(N2094,N2149,N2204,N2259) -> 0
A2975: Prairie Hills Schools Total | B2975: Audiobook (new) | C2975: =SUM(C2095,C2150,C2205,C2260) -> 0 | D2975: =SUM(D2095,D2150,D2205,D2260) -> 0 | E2975: =SUM(E2095,E2150,E2205,E2260) -> 0 | F2975: =SUM(F2095,F2150,F2205,F2260) -> 0 | G2975: =SUM(G2095,G2150,G2205,G2260) -> 0 | H2975: =SUM(H2095,H2150,H2205,H2260) -> 0 | I2975: =SUM(I2095,I2150,I2205,I2260) -> 0 | J2975: =SUM(J2095,J2150,J2205,J2260) -> 0 | ... N2975: =SUM(N2095,N2150,N2205,N2260) -> 0
A2976: Prairie Hills Schools Total | B2976: Audiobook (preloaded player) | C2976: =SUM(C2096,C2151,C2206,C2261) -> 0 | D2976: =SUM(D2096,D2151,D2206,D2261) -> 0 | E2976: =SUM(E2096,E2151,E2206,E2261) -> 0 | F2976: =SUM(F2096,F2151,F2206,F2261) -> 0 | G2976: =SUM(G2096,G2151,G2206,G2261) -> 0 | H2976: =SUM(H2096,H2151,H2206,H2261) -> 0 | I2976: =SUM(I2096,I2151,I2206,I2261) -> 0 | J2976: =SUM(J2096,J2151,J2206,J2261) -> 0 | ... N2976: =SUM(N2096,N2151,N2206,N2261) -> 0
A2977: Prairie Hills Schools Total | B2977: Book | C2977: =SUM(C2097,C2152,C2207,C2262) -> 0 | D2977: =SUM(D2097,D2152,D2207,D2262) -> 0 | E2977: =SUM(E2097,E2152,E2207,E2262) -> 0 | F2977: =SUM(F2097,F2152,F2207,F2262) -> 0 | G2977: =SUM(G2097,G2152,G2207,G2262) -> 0 | H2977: =SUM(H2097,H2152,H2207,H2262) -> 0 | I2977: =SUM(I2097,I2152,I2207,I2262) -> 0 | J2977: =SUM(J2097,J2152,J2207,J2262) -> 0 | ... N2977: =SUM(N2097,N2152,N2207,N2262) -> 0
A2978: Prairie Hills Schools Total | B2978: Book - School District 454 | C2978: =SUM(C2098,C2153,C2208,C2263) -> 0 | D2978: =SUM(D2098,D2153,D2208,D2263) -> 0 | E2978: =SUM(E2098,E2153,E2208,E2263) -> 0 | F2978: =SUM(F2098,F2153,F2208,F2263) -> 0 | G2978: =SUM(G2098,G2153,G2208,G2263) -> 0 | H2978: =SUM(H2098,H2153,H2208,H2263) -> 0 | I2978: =SUM(I2098,I2153,I2208,I2263) -> 0 | J2978: =SUM(J2098,J2153,J2208,J2263) -> 0 | ... N2978: =SUM(N2098,N2153,N2208,N2263) -> 0
A2979: Prairie Hills Schools Total | B2979: Book (local requests only) | C2979: =SUM(C2099,C2154,C2209,C2264) -> 0 | D2979: =SUM(D2099,D2154,D2209,D2264) -> 0 | E2979: =SUM(E2099,E2154,E2209,E2264) -> 0 | F2979: =SUM(F2099,F2154,F2209,F2264) -> 0 | G2979: =SUM(G2099,G2154,G2209,G2264) -> 0 | H2979: =SUM(H2099,H2154,H2209,H2264) -> 0 | I2979: =SUM(I2099,I2154,I2209,I2264) -> 0 | J2979: =SUM(J2099,J2154,J2209,J2264) -> 0 | ... N2979: =SUM(N2099,N2154,N2209,N2264) -> 0
A2980: Prairie Hills Schools Total | B2980: Book (new) | C2980: =SUM(C2100,C2155,C2210,C2265) -> 0 | D2980: =SUM(D2100,D2155,D2210,D2265) -> 0 | E2980: =SUM(E2100,E2155,E2210,E2265) -> 0 | F2980: =SUM(F2100,F2155,F2210,F2265) -> 0 | G2980: =SUM(G2100,G2155,G2210,G2265) -> 0 | H2980: =SUM(H2100,H2155,H2210,H2265) -> 0 | I2980: =SUM(I2100,I2155,I2210,I2265) -> 0 | J2980: =SUM(J2100,J2155,J2210,J2265) -> 0 | ... N2980: =SUM(N2100,N2155,N2210,N2265) -> 0
A2981: Prairie Hills Schools Total | B2981: Book (no requests allowed) | C2981: =SUM(C2101,C2156,C2211,C2266) -> 0 | D2981: =SUM(D2101,D2156,D2211,D2266) -> 0 | E2981: =SUM(E2101,E2156,E2211,E2266) -> 0 | F2981: =SUM(F2101,F2156,F2211,F2266) -> 0 | G2981: =SUM(G2101,G2156,G2211,G2266) -> 0 | H2981: =SUM(H2101,H2156,H2211,H2266) -> 0 | I2981: =SUM(I2101,I2156,I2211,I2266) -> 0 | J2981: =SUM(J2101,J2156,J2211,J2266) -> 0 | ... N2981: =SUM(N2101,N2156,N2211,N2266) -> 0
A2982: Prairie Hills Schools Total | B2982: Book club set | C2982: =SUM(C2102,C2157,C2212,C2267) -> 0 | D2982: =SUM(D2102,D2157,D2212,D2267) -> 0 | E2982: =SUM(E2102,E2157,E2212,E2267) -> 0 | F2982: =SUM(F2102,F2157,F2212,F2267) -> 0 | G2982: =SUM(G2102,G2157,G2212,G2267) -> 0 | H2982: =SUM(H2102,H2157,H2212,H2267) -> 0 | I2982: =SUM(I2102,I2157,I2212,I2267) -> 0 | J2982: =SUM(J2102,J2157,J2212,J2267) -> 0 | ... N2982: =SUM(N2102,N2157,N2212,N2267) -> 0
A2983: Prairie Hills Schools Total | B2983: Bundle | C2983: =SUM(C2103,C2158,C2213,C2268) -> 0 | D2983: =SUM(D2103,D2158,D2213,D2268) -> 0 | E2983: =SUM(E2103,E2158,E2213,E2268) -> 0 | F2983: =SUM(F2103,F2158,F2213,F2268) -> 0 | G2983: =SUM(G2103,G2158,G2213,G2268) -> 0 | H2983: =SUM(H2103,H2158,H2213,H2268) -> 0 | I2983: =SUM(I2103,I2158,I2213,I2268) -> 0 | J2983: =SUM(J2103,J2158,J2213,J2268) -> 0 | ... N2983: =SUM(N2103,N2158,N2213,N2268) -> 0
... A3026: Prairie Hills Schools Total | B3026: Video game | C3026: =SUM(C2146,C2201,C2256,C2311) -> 0 | D3026: =SUM(D2146,D2201,D2256,D2311) -> 0 | E3026: =SUM(E2146,E2201,E2256,E2311) -> 0 | F3026: =SUM(F2146,F2201,F2256,F2311) -> 0 | G3026: =SUM(G2146,G2201,G2256,G2311) -> 0 | H3026: =SUM(H2146,H2201,H2256,H2311) -> 0 | I3026: =SUM(I2146,I2201,I2256,I2311) -> 0 | J3026: =SUM(J2146,J2201,J2256,J2311) -> 0 | ... N3026: =SUM(N2146,N2201,N2256,N2311) -> 0

Sheet November
A1: branchname | B1: ITEM TYPE | C1: TOTAL ITEMS | D1: ADULT ITEMS | E1: YOUNG ADULT ITEMS | F1: JUVENILE ITEMS | G1: TOTAL ADDED LM | H1: ADULT ADDED LM | I1: YOUNG ADULT ADDED LM | J1: JUVENILE ADDED LM | K1: TOTAL DELETED LM | L1: ADULT DELETED LM | M1: YOUNG ADULT DELETED LM | N1: JUVENILE DELETED LM
A2: Atchison Public Library | B2: (Unclassified)
A3: Atchison Public Library | B3: Audiobook (CDs or cassettes)
A4: Atchison Public Library | B4: Audiobook (digital media)
A5: Atchison Public Library | B5: Audiobook (new)
A6: Atchison Public Library | B6: Audiobook (preloaded player)
A7: Atchison Public Library | B7: Book
A8: Atchison Public Library | B8: Book - School District 454
A9: Atchison Public Library | B9: Book (local requests only)
A10: Atchison Public Library | B10: Book (new)
A11: Atchison Public Library | B11: Book (no requests allowed)
A12: Atchison Public Library | B12: Book club set
A13: Atchison Public Library | B13: Bundle
... A2916: Winchester Public Library | B2916: Video game
A2917: Doniphan County Total | B2917: (Unclassified) | C2917: =SUM(C552,C607,C662,C717) -> 0 | D2917: =SUM(D552,D607,D662,D717) -> 0 | E2917: =SUM(E552,E607,E662,E717) -> 0 | F2917: =SUM(F552,F607,F662,F717) -> 0 | G2917: =SUM(G552,G607,G662,G717) -> 0 | H2917: =SUM(H552,H607,H662,H717) -> 0 | I2917: =SUM(I552,I607,I662,I717) -> 0 | J2917: =SUM(J552,J607,J662,J717) -> 0 | ... N2917: =SUM(N552,N607,N662,N717) -> 0
A2918: Doniphan County Total | B2918: Audiobook (CDs or cassettes) | C2918: =SUM(C553,C608,C663,C718) -> 0 | D2918: =SUM(D553,D608,D663,D718) -> 0 | E2918: =SUM(E553,E608,E663,E718) -> 0 | F2918: =SUM(F553,F608,F663,F718) -> 0 | G2918: =SUM(G553,G608,G663,G718) -> 0 | H2918: =SUM(H553,H608,H663,H718) -> 0 | I2918: =SUM(I553,I608,I663,I718) -> 0 | J2918: =SUM(J553,J608,J663,J718) -> 0 | ... N2918: =SUM(N553,N608,N663,N718) -> 0
A2919: Doniphan County Total | B2919: Audiobook (digital media) | C2919: =SUM(C554,C609,C664,C719) -> 0 | D2919: =SUM(D554,D609,D664,D719) -> 0 | E2919: =SUM(E554,E609,E664,E719) -> 0 | F2919: =SUM(F554,F609,F664,F719) -> 0 | G2919: =SUM(G554,G609,G664,G719) -> 0 | H2919: =SUM(H554,H609,H664,H719) -> 0 | I2919: =SUM(I554,I609,I664,I719) -> 0 | J2919: =SUM(J554,J609,J664,J719) -> 0 | ... N2919: =SUM(N554,N609,N664,N719) -> 0
A2920: Doniphan County Total | B2920: Audiobook (new) | C2920: =SUM(C555,C610,C665,C720) -> 0 | D2920: =SUM(D555,D610,D665,D720) -> 0 | E2920: =SUM(E555,E610,E665,E720) -> 0 | F2920: =SUM(F555,F610,F665,F720) -> 0 | G2920: =SUM(G555,G610,G665,G720) -> 0 | H2920: =SUM(H555,H610,H665,H720) -> 0 | I2920: =SUM(I555,I610,I665,I720) -> 0 | J2920: =SUM(J555,J610,J665,J720) -> 0 | ... N2920: =SUM(N555,N610,N665,N720) -> 0
A2921: Doniphan County Total | B2921: Audiobook (preloaded player) | C2921: =SUM(C556,C611,C666,C721) -> 0 | D2921: =SUM(D556,D611,D666,D721) -> 0 | E2921: =SUM(E556,E611,E666,E721) -> 0 | F2921: =SUM(F556,F611,F666,F721) -> 0 | G2921: =SUM(G556,G611,G666,G721) -> 0 | H2921: =SUM(H556,H611,H666,H721) -> 0 | I2921: =SUM(I556,I611,I666,I721) -> 0 | J2921: =SUM(J556,J611,J666,J721) -> 0 | ... N2921: =SUM(N556,N611,N666,N721) -> 0
A2922: Doniphan County Total | B2922: Book | C2922: =SUM(C557,C612,C667,C722) -> 0 | D2922: =SUM(D557,D612,D667,D722) -> 0 | E2922: =SUM(E557,E612,E667,E722) -> 0 | F2922: =SUM(F557,F612,F667,F722) -> 0 | G2922: =SUM(G557,G612,G667,G722) -> 0 | H2922: =SUM(H557,H612,H667,H722) -> 0 | I2922: =SUM(I557,I612,I667,I722) -> 0 | J2922: =SUM(J557,J612,J667,J722) -> 0 | ... N2922: =SUM(N557,N612,N667,N722) -> 0
A2923: Doniphan County Total | B2923: Book - School District 454 | C2923: =SUM(C558,C613,C668,C723) -> 0 | D2923: =SUM(D558,D613,D668,D723) -> 0 | E2923: =SUM(E558,E613,E668,E723) -> 0 | F2923: =SUM(F558,F613,F668,F723) -> 0 | G2923: =SUM(G558,G613,G668,G723) -> 0 | H2923: =SUM(H558,H613,H668,H723) -> 0 | I2923: =SUM(I558,I613,I668,I723) -> 0 | J2923: =SUM(J558,J613,J668,J723) -> 0 | ... N2923: =SUM(N558,N613,N668,N723) -> 0
A2924: Doniphan County Total | B2924: Book (local requests only) | C2924: =SUM(C559,C614,C669,C724) -> 0 | D2924: =SUM(D559,D614,D669,D724) -> 0 | E2924: =SUM(E559,E614,E669,E724) -> 0 | F2924: =SUM(F559,F614,F669,F724) -> 0 | G2924: =SUM(G559,G614,G669,G724) -> 0 | H2924: =SUM(H559,H614,H669,H724) -> 0 | I2924: =SUM(I559,I614,I669,I724) -> 0 | J2924: =SUM(J559,J614,J669,J724) -> 0 | ... N2924: =SUM(N559,N614,N669,N724) -> 0
A2925: Doniphan County Total | B2925: Book (new) | C2925: =SUM(C560,C615,C670,C725) -> 0 | D2925: =SUM(D560,D615,D670,D725) -> 0 | E2925: =SUM(E560,E615,E670,E725) -> 0 | F2925: =SUM(F560,F615,F670,F725) -> 0 | G2925: =SUM(G560,G615,G670,G725) -> 0 | H2925: =SUM(H560,H615,H670,H725) -> 0 | I2925: =SUM(I560,I615,I670,I725) -> 0 | J2925: =SUM(J560,J615,J670,J725) -> 0 | ... N2925: =SUM(N560,N615,N670,N725) -> 0
A2926: Doniphan County Total | B2926: Book (no requests allowed) | C2926: =SUM(C561,C616,C671,C726) -> 0 | D2926: =SUM(D561,D616,D671,D726) -> 0 | E2926: =SUM(E561,E616,E671,E726) -> 0 | F2926: =SUM(F561,F616,F671,F726) -> 0 | G2926: =SUM(G561,G616,G671,G726) -> 0 | H2926: =SUM(H561,H616,H671,H726) -> 0 | I2926: =SUM(I561,I616,I671,I726) -> 0 | J2926: =SUM(J561,J616,J671,J726) -> 0 | ... N2926: =SUM(N561,N616,N671,N726) -> 0
A2927: Doniphan County Total | B2927: Book club set | C2927: =SUM(C562,C617,C672,C727) -> 0 | D2927: =SUM(D562,D617,D672,D727) -> 0 | E2927: =SUM(E562,E617,E672,E727) -> 0 | F2927: =SUM(F562,F617,F672,F727) -> 0 | G2927: =SUM(G562,G617,G672,G727) -> 0 | H2927: =SUM(H562,H617,H672,H727) -> 0 | I2927: =SUM(I562,I617,I672,I727) -> 0 | J2927: =SUM(J562,J617,J672,J727) -> 0 | ... N2927: =SUM(N562,N617,N672,N727) -> 0
A2928: Doniphan County Total | B2928: Bundle | C2928: =SUM(C563,C618,C673,C728) -> 0 | D2928: =SUM(D563,D618,D673,D728) -> 0 | E2928: =SUM(E563,E618,E673,E728) -> 0 | F2928: =SUM(F563,F618,F673,F728) -> 0 | G2928: =SUM(G563,G618,G673,G728) -> 0 | H2928: =SUM(H563,H618,H673,H728) -> 0 | I2928: =SUM(I563,I618,I673,I728) -> 0 | J2928: =SUM(J563,J618,J673,J728) -> 0 | ... N2928: =SUM(N563,N618,N673,N728) -> 0
... A2971: Doniphan County Total | B2971: Video game | C2971: =SUM(C606,C661,C716,C771) -> 0 | D2971: =SUM(D606,D661,D716,D771) -> 0 | E2971: =SUM(E606,E661,E716,E771) -> 0 | F2971: =SUM(F606,F661,F716,F771) -> 0 | G2971: =SUM(G606,G661,G716,G771) -> 0 | H2971: =SUM(H606,H661,H716,H771) -> 0 | I2971: =SUM(I606,I661,I716,I771) -> 0 | J2971: =SUM(J606,J661,J716,J771) -> 0 | ... N2971: =SUM(N606,N661,N716,N771) -> 0
A2972: Prairie Hills Schools Total | B2972: (Unclassified) | C2972: =SUM(C2092,C2147,C2202,C2257) -> 0 | D2972: =SUM(D2092,D2147,D2202,D2257) -> 0 | E2972: =SUM(E2092,E2147,E2202,E2257) -> 0 | F2972: =SUM(F2092,F2147,F2202,F2257) -> 0 | G2972: =SUM(G2092,G2147,G2202,G2257) -> 0 | H2972: =SUM(H2092,H2147,H2202,H2257) -> 0 | I2972: =SUM(I2092,I2147,I2202,I2257) -> 0 | J2972: =SUM(J2092,J2147,J2202,J2257) -> 0 | ... N2972: =SUM(N2092,N2147,N2202,N2257) -> 0
A2973: Prairie Hills Schools Total | B2973: Audiobook (CDs or cassettes) | C2973: =SUM(C2093,C2148,C2203,C2258) -> 0 | D2973: =SUM(D2093,D2148,D2203,D2258) -> 0 | E2973: =SUM(E2093,E2148,E2203,E2258) -> 0 | F2973: =SUM(F2093,F2148,F2203,F2258) -> 0 | G2973: =SUM(G2093,G2148,G2203,G2258) -> 0 | H2973: =SUM(H2093,H2148,H2203,H2258) -> 0 | I2973: =SUM(I2093,I2148,I2203,I2258) -> 0 | J2973: =SUM(J2093,J2148,J2203,J2258) -> 0 | ... N2973: =SUM(N2093,N2148,N2203,N2258) -> 0
A2974: Prairie Hills Schools Total | B2974: Audiobook (digital media) | C2974: =SUM(C2094,C2149,C2204,C2259) -> 0 | D2974: =SUM(D2094,D2149,D2204,D2259) -> 0 | E2974: =SUM(E2094,E2149,E2204,E2259) -> 0 | F2974: =SUM(F2094,F2149,F2204,F2259) -> 0 | G2974: =SUM(G2094,G2149,G2204,G2259) -> 0 | H2974: =SUM(H2094,H2149,H2204,H2259) -> 0 | I2974: =SUM(I2094,I2149,I2204,I2259) -> 0 | J2974: =SUM(J2094,J2149,J2204,J2259) -> 0 | ... N2974: =SUM(N2094,N2149,N2204,N2259) -> 0
A2975: Prairie Hills Schools Total | B2975: Audiobook (new) | C2975: =SUM(C2095,C2150,C2205,C2260) -> 0 | D2975: =SUM(D2095,D2150,D2205,D2260) -> 0 | E2975: =SUM(E2095,E2150,E2205,E2260) -> 0 | F2975: =SUM(F2095,F2150,F2205,F2260) -> 0 | G2975: =SUM(G2095,G2150,G2205,G2260) -> 0 | H2975: =SUM(H2095,H2150,H2205,H2260) -> 0 | I2975: =SUM(I2095,I2150,I2205,I2260) -> 0 | J2975: =SUM(J2095,J2150,J2205,J2260) -> 0 | ... N2975: =SUM(N2095,N2150,N2205,N2260) -> 0
A2976: Prairie Hills Schools Total | B2976: Audiobook (preloaded player) | C2976: =SUM(C2096,C2151,C2206,C2261) -> 0 | D2976: =SUM(D2096,D2151,D2206,D2261) -> 0 | E2976: =SUM(E2096,E2151,E2206,E2261) -> 0 | F2976: =SUM(F2096,F2151,F2206,F2261) -> 0 | G2976: =SUM(G2096,G2151,G2206,G2261) -> 0 | H2976: =SUM(H2096,H2151,H2206,H2261) -> 0 | I2976: =SUM(I2096,I2151,I2206,I2261) -> 0 | J2976: =SUM(J2096,J2151,J2206,J2261) -> 0 | ... N2976: =SUM(N2096,N2151,N2206,N2261) -> 0
A2977: Prairie Hills Schools Total | B2977: Book | C2977: =SUM(C2097,C2152,C2207,C2262) -> 0 | D2977: =SUM(D2097,D2152,D2207,D2262) -> 0 | E2977: =SUM(E2097,E2152,E2207,E2262) -> 0 | F2977: =SUM(F2097,F2152,F2207,F2262) -> 0 | G2977: =SUM(G2097,G2152,G2207,G2262) -> 0 | H2977: =SUM(H2097,H2152,H2207,H2262) -> 0 | I2977: =SUM(I2097,I2152,I2207,I2262) -> 0 | J2977: =SUM(J2097,J2152,J2207,J2262) -> 0 | ... N2977: =SUM(N2097,N2152,N2207,N2262) -> 0
A2978: Prairie Hills Schools Total | B2978: Book - School District 454 | C2978: =SUM(C2098,C2153,C2208,C2263) -> 0 | D2978: =SUM(D2098,D2153,D2208,D2263) -> 0 | E2978: =SUM(E2098,E2153,E2208,E2263) -> 0 | F2978: =SUM(F2098,F2153,F2208,F2263) -> 0 | G2978: =SUM(G2098,G2153,G2208,G2263) -> 0 | H2978: =SUM(H2098,H2153,H2208,H2263) -> 0 | I2978: =SUM(I2098,I2153,I2208,I2263) -> 0 | J2978: =SUM(J2098,J2153,J2208,J2263) -> 0 | ... N2978: =SUM(N2098,N2153,N2208,N2263) -> 0
A2979: Prairie Hills Schools Total | B2979: Book (local requests only) | C2979: =SUM(C2099,C2154,C2209,C2264) -> 0 | D2979: =SUM(D2099,D2154,D2209,D2264) -> 0 | E2979: =SUM(E2099,E2154,E2209,E2264) -> 0 | F2979: =SUM(F2099,F2154,F2209,F2264) -> 0 | G2979: =SUM(G2099,G2154,G2209,G2264) -> 0 | H2979: =SUM(H2099,H2154,H2209,H2264) -> 0 | I2979: =SUM(I2099,I2154,I2209,I2264) -> 0 | J2979: =SUM(J2099,J2154,J2209,J2264) -> 0 | ... N2979: =SUM(N2099,N2154,N2209,N2264) -> 0
A2980: Prairie Hills Schools Total | B2980: Book (new) | C2980: =SUM(C2100,C2155,C2210,C2265) -> 0 | D2980: =SUM(D2100,D2155,D2210,D2265) -> 0 | E2980: =SUM(E2100,E2155,E2210,E2265) -> 0 | F2980: =SUM(F2100,F2155,F2210,F2265) -> 0 | G2980: =SUM(G2100,G2155,G2210,G2265) -> 0 | H2980: =SUM(H2100,H2155,H2210,H2265) -> 0 | I2980: =SUM(I2100,I2155,I2210,I2265) -> 0 | J2980: =SUM(J2100,J2155,J2210,J2265) -> 0 | ... N2980: =SUM(N2100,N2155,N2210,N2265) -> 0
A2981: Prairie Hills Schools Total | B2981: Book (no requests allowed) | C2981: =SUM(C2101,C2156,C2211,C2266) -> 0 | D2981: =SUM(D2101,D2156,D2211,D2266) -> 0 | E2981: =SUM(E2101,E2156,E2211,E2266) -> 0 | F2981: =SUM(F2101,F2156,F2211,F2266) -> 0 | G2981: =SUM(G2101,G2156,G2211,G2266) -> 0 | H2981: =SUM(H2101,H2156,H2211,H2266) -> 0 | I2981: =SUM(I2101,I2156,I2211,I2266) -> 0 | J2981: =SUM(J2101,J2156,J2211,J2266) -> 0 | ... N2981: =SUM(N2101,N2156,N2211,N2266) -> 0
A2982: Prairie Hills Schools Total | B2982: Book club set | C2982: =SUM(C2102,C2157,C2212,C2267) -> 0 | D2982: =SUM(D2102,D2157,D2212,D2267) -> 0 | E2982: =SUM(E2102,E2157,E2212,E2267) -> 0 | F2982: =SUM(F2102,F2157,F2212,F2267) -> 0 | G2982: =SUM(G2102,G2157,G2212,G2267) -> 0 | H2982: =SUM(H2102,H2157,H2212,H2267) -> 0 | I2982: =SUM(I2102,I2157,I2212,I2267) -> 0 | J2982: =SUM(J2102,J2157,J2212,J2267) -> 0 | ... N2982: =SUM(N2102,N2157,N2212,N2267) -> 0
A2983: Prairie Hills Schools Total | B2983: Bundle | C2983: =SUM(C2103,C2158,C2213,C2268) -> 0 | D2983: =SUM(D2103,D2158,D2213,D2268) -> 0 | E2983: =SUM(E2103,E2158,E2213,E2268) -> 0 | F2983: =SUM(F2103,F2158,F2213,F2268) -> 0 | G2983: =SUM(G2103,G2158,G2213,G2268) -> 0 | H2983: =SUM(H2103,H2158,H2213,H2268) -> 0 | I2983: =SUM(I2103,I2158,I2213,I2268) -> 0 | J2983: =SUM(J2103,J2158,J2213,J2268) -> 0 | ... N2983: =SUM(N2103,N2158,N2213,N2268) -> 0
... A3026: Prairie Hills Schools Total | B3026: Video game | C3026: =SUM(C2146,C2201,C2256,C2311) -> 0 | D3026: =SUM(D2146,D2201,D2256,D2311) -> 0 | E3026: =SUM(E2146,E2201,E2256,E2311) -> 0 | F3026: =SUM(F2146,F2201,F2256,F2311) -> 0 | G3026: =SUM(G2146,G2201,G2256,G2311) -> 0 | H3026: =SUM(H2146,H2201,H2256,H2311) -> 0 | I3026: =SUM(I2146,I2201,I2256,I2311) -> 0 | J3026: =SUM(J2146,J2201,J2256,J2311) -> 0 | ... N3026: =SUM(N2146,N2201,N2256,N2311) -> 0

Sheet December
A1: branchname | B1: ITEM TYPE | C1: TOTAL ITEMS | D1: ADULT ITEMS | E1: YOUNG ADULT ITEMS | F1: JUVENILE ITEMS | G1: TOTAL ADDED LM | H1: ADULT ADDED LM | I1: YOUNG ADULT ADDED LM | J1: JUVENILE ADDED LM | K1: TOTAL DELETED LM | L1: ADULT DELETED LM | M1: YOUNG ADULT DELETED LM | N1: JUVENILE DELETED LM
A2: Atchison Public Library | B2: (Unclassified)
A3: Atchison Public Library | B3: Audiobook (CDs or cassettes)
A4: Atchison Public Library | B4: Audiobook (digital media)
A5: Atchison Public Library | B5: Audiobook (new)
A6: Atchison Public Library | B6: Audiobook (preloaded player)
A7: Atchison Public Library | B7: Book
A8: Atchison Public Library | B8: Book - School District 454
A9: Atchison Public Library | B9: Book (local requests only)
A10: Atchison Public Library | B10: Book (new)
A11: Atchison Public Library | B11: Book (no requests allowed)
A12: Atchison Public Library | B12: Book club set
A13: Atchison Public Library | B13: Bundle
... A2916: Winchester Public Library | B2916: Video game
A2917: Doniphan County Total | B2917: (Unclassified) | C2917: =SUM(C552,C607,C662,C717) -> 0 | D2917: =SUM(D552,D607,D662,D717) -> 0 | E2917: =SUM(E552,E607,E662,E717) -> 0 | F2917: =SUM(F552,F607,F662,F717) -> 0 | G2917: =SUM(G552,G607,G662,G717) -> 0 | H2917: =SUM(H552,H607,H662,H717) -> 0 | I2917: =SUM(I552,I607,I662,I717) -> 0 | J2917: =SUM(J552,J607,J662,J717) -> 0 | ... N2917: =SUM(N552,N607,N662,N717) -> 0
A2918: Doniphan County Total | B2918: Audiobook (CDs or cassettes) | C2918: =SUM(C553,C608,C663,C718) -> 0 | D2918: =SUM(D553,D608,D663,D718) -> 0 | E2918: =SUM(E553,E608,E663,E718) -> 0 | F2918: =SUM(F553,F608,F663,F718) -> 0 | G2918: =SUM(G553,G608,G663,G718) -> 0 | H2918: =SUM(H553,H608,H663,H718) -> 0 | I2918: =SUM(I553,I608,I663,I718) -> 0 | J2918: =SUM(J553,J608,J663,J718) -> 0 | ... N2918: =SUM(N553,N608,N663,N718) -> 0
A2919: Doniphan County Total | B2919: Audiobook (digital media) | C2919: =SUM(C554,C609,C664,C719) -> 0 | D2919: =SUM(D554,D609,D664,D719) -> 0 | E2919: =SUM(E554,E609,E664,E719) -> 0 | F2919: =SUM(F554,F609,F664,F719) -> 0 | G2919: =SUM(G554,G609,G664,G719) -> 0 | H2919: =SUM(H554,H609,H664,H719) -> 0 | I2919: =SUM(I554,I609,I664,I719) -> 0 | J2919: =SUM(J554,J609,J664,J719) -> 0 | ... N2919: =SUM(N554,N609,N664,N719) -> 0
A2920: Doniphan County Total | B2920: Audiobook (new) | C2920: =SUM(C555,C610,C665,C720) -> 0 | D2920: =SUM(D555,D610,D665,D720) -> 0 | E2920: =SUM(E555,E610,E665,E720) -> 0 | F2920: =SUM(F555,F610,F665,F720) -> 0 | G2920: =SUM(G555,G610,G665,G720) -> 0 | H2920: =SUM(H555,H610,H665,H720) -> 0 | I2920: =SUM(I555,I610,I665,I720) -> 0 | J2920: =SUM(J555,J610,J665,J720) -> 0 | ... N2920: =SUM(N555,N610,N665,N720) -> 0
A2921: Doniphan County Total | B2921: Audiobook (preloaded player) | C2921: =SUM(C556,C611,C666,C721) -> 0 | D2921: =SUM(D556,D611,D666,D721) -> 0 | E2921: =SUM(E556,E611,E666,E721) -> 0 | F2921: =SUM(F556,F611,F666,F721) -> 0 | G2921: =SUM(G556,G611,G666,G721) -> 0 | H2921: =SUM(H556,H611,H666,H721) -> 0 | I2921: =SUM(I556,I611,I666,I721) -> 0 | J2921: =SUM(J556,J611,J666,J721) -> 0 | ... N2921: =SUM(N556,N611,N666,N721) -> 0
A2922: Doniphan County Total | B2922: Book | C2922: =SUM(C557,C612,C667,C722) -> 0 | D2922: =SUM(D557,D612,D667,D722) -> 0 | E2922: =SUM(E557,E612,E667,E722) -> 0 | F2922: =SUM(F557,F612,F667,F722) -> 0 | G2922: =SUM(G557,G612,G667,G722) -> 0 | H2922: =SUM(H557,H612,H667,H722) -> 0 | I2922: =SUM(I557,I612,I667,I722) -> 0 | J2922: =SUM(J557,J612,J667,J722) -> 0 | ... N2922: =SUM(N557,N612,N667,N722) -> 0
A2923: Doniphan County Total | B2923: Book - School District 454 | C2923: =SUM(C558,C613,C668,C723) -> 0 | D2923: =SUM(D558,D613,D668,D723) -> 0 | E2923: =SUM(E558,E613,E668,E723) -> 0 | F2923: =SUM(F558,F613,F668,F723) -> 0 | G2923: =SUM(G558,G613,G668,G723) -> 0 | H2923: =SUM(H558,H613,H668,H723) -> 0 | I2923: =SUM(I558,I613,I668,I723) -> 0 | J2923: =SUM(J558,J613,J668,J723) -> 0 | ... N2923: =SUM(N558,N613,N668,N723) -> 0
A2924: Doniphan County Total | B2924: Book (local requests only) | C2924: =SUM(C559,C614,C669,C724) -> 0 | D2924: =SUM(D559,D614,D669,D724) -> 0 | E2924: =SUM(E559,E614,E669,E724) -> 0 | F2924: =SUM(F559,F614,F669,F724) -> 0 | G2924: =SUM(G559,G614,G669,G724) -> 0 | H2924: =SUM(H559,H614,H669,H724) -> 0 | I2924: =SUM(I559,I614,I669,I724) -> 0 | J2924: =SUM(J559,J614,J669,J724) -> 0 | ... N2924: =SUM(N559,N614,N669,N724) -> 0
A2925: Doniphan County Total | B2925: Book (new) | C2925: =SUM(C560,C615,C670,C725) -> 0 | D2925: =SUM(D560,D615,D670,D725) -> 0 | E2925: =SUM(E560,E615,E670,E725) -> 0 | F2925: =SUM(F560,F615,F670,F725) -> 0 | G2925: =SUM(G560,G615,G670,G725) -> 0 | H2925: =SUM(H560,H615,H670,H725) -> 0 | I2925: =SUM(I560,I615,I670,I725) -> 0 | J2925: =SUM(J560,J615,J670,J725) -> 0 | ... N2925: =SUM(N560,N615,N670,N725) -> 0
A2926: Doniphan County Total | B2926: Book (no requests allowed) | C2926: =SUM(C561,C616,C671,C726) -> 0 | D2926: =SUM(D561,D616,D671,D726) -> 0 | E2926: =SUM(E561,E616,E671,E726) -> 0 | F2926: =SUM(F561,F616,F671,F726) -> 0 | G2926: =SUM(G561,G616,G671,G726) -> 0 | H2926: =SUM(H561,H616,H671,H726) -> 0 | I2926: =SUM(I561,I616,I671,I726) -> 0 | J2926: =SUM(J561,J616,J671,J726) -> 0 | ... N2926: =SUM(N561,N616,N671,N726) -> 0
