Workbook

Sheet January
A1: Library | B1: Other Next library materials checked out at our library | C1: Our materials checked out at other Next libraries | D1: NET | E1: Net borrower | F1: Net lender | G1: Borrowed to lent ratio
A2: Atchison Public Library | B2: 1441 | C2: 1299 | D2: 142 | E2: We borrowerd more than we lent | G2: 1.11 : 1
A3: Baldwin City Public Library | B3: 671 | C3: 419 | D3: 252 | E3: We borrowerd more than we lent | G3: 1.60 : 1
A4: Basehor Community Library | B4: 1369 | C4: 1352 | D4: 17 | E4: We borrowerd more than we lent | G4: 1.01 : 1
A5: Bern Community Library | B5: 28 | C5: 143 | D5: -115 | F5: We lent more than we borrowed | G5: 0.20 : 1
A6: Bonner Springs City Library | B6: 1162 | C6: 1131 | D6: 31 | E6: We borrowerd more than we lent | G6: 1.03 : 1
A7: Burlingame Community Library | B7: 217 | C7: 180 | D7: 37 | E7: We borrowerd more than we lent | G7: 1.21 : 1
A8: Carbondale City Library | B8: 111 | C8: 171 | D8: -60 | F8: We lent more than we borrowed | G8: 0.65 : 1
A9: Centralia Community Library | B9: 73 | C9: 66 | D9: 7 | E9: We borrowerd more than we lent | G9: 1.11 : 1
A10: Corning City Library | B10: 0 | C10: 19 | D10: -19 | F10: We lent more than we borrowed | G10: 0.00 : 1
A11: Digital Content | B11: 0 | C11: 0 | D11: 0
A12: Doniphan County Library - Elwood | B12: 7 | C12: 22 | D12: -15 | F12: We lent more than we borrowed | G12: 0.32 : 1
A13: Doniphan County Library - Highland | B13: 42 | C13: 54 | D13: -12 | F13: We lent more than we borrowed | G13: 0.78 : 1
A14: Doniphan County Library - Troy | B14: 168 | C14: 270 | D14: -102 | F14: We lent more than we borrowed | G14: 0.62 : 1
A15: Doniphan County Library - Wathena | B15: 55 | C15: 160 | D15: -105 | F15: We lent more than we borrowed | G15: 0.34 : 1
A16: Effingham Community Library | B16: 74 | C16: 237 | D16: -163 | F16: We lent more than we borrowed | G16: 0.31 : 1
A17: Eudora Community Library | B17: 694 | C17: 435 | D17: 259 | E17: We borrowerd more than we lent | G17: 1.60 : 1
A18: Everest, Barnes Reading Room | B18: 89 | C18: 94 | D18: -5 | F18: We lent more than we borrowed | G18: 0.95 : 1
A19: Hiawatha, Morrill Public Library | B19: 485 | C19: 302 | D19: 183 | E19: We borrowerd more than we lent | G19: 1.61 : 1
A20: Highland Community College | B20: 3 | C20: 55 | D20: -52 | F20: We lent more than we borrowed | G20: 0.05 : 1
A21: Holton, Beck-Bookman Library | B21: 501 | C21: 474 | D21: 27 | E21: We borrowerd more than we lent | G21: 1.06 : 1
A22: Horton Public Library | B22: 90 | C22: 225 | D22: -135 | F22: We lent more than we borrowed | G22: 0.40 : 1
A23: Lansing Community Library | B23: 613 | C23: 586 | D23: 27 | E23: We borrowerd more than we lent | G23: 1.05 : 1
A24: Leavenworth Public Library | B24: 1809 | C24: 1166 | D24: 643 | E24: We borrowerd more than we lent | G24: 1.55 : 1
A25: Linwood Community Library | B25: 172 | C25: 356 | D25: -184 | F25: We lent more than we borrowed | G25: 0.48 : 1
A26: Louisburg Library | B26: 0 | C26: 0 | D26: 0
A27: Lyndon Carnegie Library | B27: 231 | C27: 146 | D27: 85 | E27: We borrowerd more than we lent | G27: 1.58 : 1
A28: McLouth Public Library | B28: 132 | C28: 120 | D28: 12 | E28: We borrowerd more than we lent | G28: 1.10 : 1
A29: Meriden-Ozawkie Public Library | B29: 891 | C29: 550 | D29: 341 | E29: We borrowerd more than we lent | G29: 1.62 : 1
A30: Northeast Kansas Library System | B30: 24 | C30: 29 | D30: -5 | F30: We lent more than we borrowed | G30: 0.83 : 1
A31: Nortonville Public Library | B31: 119 | C31: 231 | D31: -112 | F31: We lent more than we borrowed | G31: 0.52 : 1
A32: Osage City Library | B32: 521 | C32: 520 | D32: 1 | E32: We borrowerd more than we lent | G32: 1.00 : 1
A33: Osawatomie Public Library | B33: 373 | C33: 407 | D33: -34 | F33: We lent more than we borrowed | G33: 0.92 : 1
A34: Oskaloosa Public Library | B34: 208 | C34: 104 | D34: 104 | E34: We borrowerd more than we lent | G34: 2.00 : 1
A35: Ottawa Library | B35: 925 | C35: 1641 | D35: -716 | F35: We lent more than we borrowed | G35: 0.56 : 1
A36: Overbrook Public Library | B36: 180 | C36: 644 | D36: -464 | F36: We lent more than we borrowed | G36: 0.28 : 1
A37: Paola Free Library | B37: 493 | C37: 460 | D37: 33 | E37: We borrowerd more than we lent | G37: 1.07 : 1
A38: Perry-Lecompton Community Library | B38: 19 | C38: 219 | D38: -200 | F38: We lent more than we borrowed | G38: 0.09 : 1
A39: Prairie Hills Schools - Axtell Public School | B39: 9 | C39: 40 | D39: -31 | F39: We lent more than we borrowed | G39: 0.23 : 1
A40: Prairie Hills Schools - Sabetha Elementary School | B40: 87 | C40: 96 | D40: -9 | F40: We lent more than we borrowed | G40: 0.91 : 1
...

Sheet February
A1: Library | B1: Other Next library materials checked out at our library | C1: Our materials checked out at other Next libraries | D1: NET | E1: Net borrower | F1: Net lender | G1: Borrowed to lent ratio
A2: Atchison Public Library | B2: 1366 | C2: 1141 | D2: 225 | E2: We borrowerd more than we lent | G2: 1.20 : 1
A3: Baldwin City Public Library | B3: 672 | C3: 360 | D3: 312 | E3: We borrowerd more than we lent | G3: 1.87 : 1
A4: Basehor Community Library | B4: 1140 | C4: 1008 | D4: 132 | E4: We borrowerd more than we lent | G4: 1.13 : 1
A5: Bern Community Library | B5: 18 | C5: 111 | D5: -93 | F5: We lent more than we borrowed | G5: 0.16 : 1
A6: Bonner Springs City Library | B6: 966 | C6: 1153 | D6: -187 | F6: We lent more than we borrowed | G6: 0.84 : 1
A7: Burlingame Community Library | B7: 169 | C7: 147 | D7: 22 | E7: We borrowerd more than we lent | G7: 1.15 : 1
A8: Carbondale City Library | B8: 107 | C8: 180 | D8: -73 | F8: We lent more than we borrowed | G8: 0.59 : 1
A9: Centralia Community Library | B9: 67 | C9: 49 | D9: 18 | E9: We borrowerd more than we lent | G9: 1.37 : 1
A10: Corning City Library | B10: 3 | C10: 31 | D10: -28 | F10: We lent more than we borrowed | G10: 0.10 : 1
A11: Digital Content | B11: 0 | C11: 0 | D11: 0
A12: Doniphan County Library - Elwood | B12: 2 | C12: 21 | D12: -19 | F12: We lent more than we borrowed | G12: 0.10 : 1
A13: Doniphan County Library - Highland | B13: 52 | C13: 80 | D13: -28 | F13: We lent more than we borrowed | G13: 0.65 : 1
A14: Doniphan County Library - Troy | B14: 126 | C14: 280 | D14: -154 | F14: We lent more than we borrowed | G14: 0.45 : 1
A15: Doniphan County Library - Wathena | B15: 46 | C15: 165 | D15: -119 | F15: We lent more than we borrowed | G15: 0.28 : 1
A16: Effingham Community Library | B16: 60 | C16: 186 | D16: -126 | F16: We lent more than we borrowed | G16: 0.32 : 1
A17: Eudora Community Library | B17: 728 | C17: 422 | D17: 306 | E17: We borrowerd more than we lent | G17: 1.73 : 1
A18: Everest, Barnes Reading Room | B18: 114 | C18: 81 | D18: 33 | E18: We borrowerd more than we lent | G18: 1.41 : 1
A19: Hiawatha, Morrill Public Library | B19: 724 | C19: 340 | D19: 384 | E19: We borrowerd more than we lent | G19: 2.13 : 1
A20: Highland Community College | B20: 4 | C20: 54 | D20: -50 | F20: We lent more than we borrowed | G20: 0.07 : 1
A21: Holton, Beck-Bookman Library | B21: 448 | C21: 385 | D21: 63 | E21: We borrowerd more than we lent | G21: 1.16 : 1
A22: Horton Public Library | B22: 129 | C22: 272 | D22: -143 | F22: We lent more than we borrowed | G22: 0.47 : 1
A23: Lansing Community Library | B23: 581 | C23: 536 | D23: 45 | E23: We borrowerd more than we lent | G23: 1.08 : 1
A24: Leavenworth Public Library | B24: 1901 | C24: 1621 | D24: 280 | E24: We borrowerd more than we lent | G24: 1.17 : 1
A25: Linwood Community Library | B25: 174 | C25: 304 | D25: -130 | F25: We lent more than we borrowed | G25: 0.57 : 1
A26: Louisburg Library | B26: 0 | C26: 0 | D26: 0
A27: Lyndon Carnegie Library | B27: 172 | C27: 150 | D27: 22 | E27: We borrowerd more than we lent | G27: 1.15 : 1
A28: McLouth Public Library | B28: 126 | C28: 144 | D28: -18 | F28: We lent more than we borrowed | G28: 0.88 : 1
A29: Meriden-Ozawkie Public Library | B29: 870 | C29: 484 | D29: 386 | E29: We borrowerd more than we lent | G29: 1.80 : 1
A30: Northeast Kansas Library System | B30: 9 | C30: 25 | D30: -16 | F30: We lent more than we borrowed | G30: 0.36 : 1
A31: Nortonville Public Library | B31: 139 | C31: 281 | D31: -142 | F31: We lent more than we borrowed | G31: 0.49 : 1
A32: Osage City Library | B32: 399 | C32: 473 | D32: -74 | F32: We lent more than we borrowed | G32: 0.84 : 1
A33: Osawatomie Public Library | B33: 384 | C33: 323 | D33: 61 | E33: We borrowerd more than we lent | G33: 1.19 : 1
A34: Oskaloosa Public Library | B34: 224 | C34: 104 | D34: 120 | E34: We borrowerd more than we lent | G34: 2.15 : 1
A35: Ottawa Library | B35: 931 | C35: 1445 | D35: -514 | F35: We lent more than we borrowed | G35: 0.64 : 1
A36: Overbrook Public Library | B36: 182 | C36: 536 | D36: -354 | F36: We lent more than we borrowed | G36: 0.34 : 1
A37: Paola Free Library | B37: 534 | C37: 443 | D37: 91 | E37: We borrowerd more than we lent | G37: 1.21 : 1
A38: Perry-Lecompton Community Library | B38: 34 | C38: 166 | D38: -132 | F38: We lent more than we borrowed | G38: 0.20 : 1
A39: Prairie Hills Schools - Axtell Public School | B39: 24 | C39: 64 | D39: -40 | F39: We lent more than we borrowed | G39: 0.38 : 1
A40: Prairie Hills Schools - Sabetha Elementary School | B40: 123 | C40: 146 | D40: -23 | F40: We lent more than we borrowed | G40: 0.84 : 1
...

Sheet March
A1: Library | B1: Other Next library materials checked out at our library | C1: Our materials checked out at other Next libraries | D1: NET | E1: Net borrower | F1: Net lender | G1: Borrowed to lent ratio
A2: Atchison Public Library | B2: 1596 | C2: 1263 | D2: 333 | E2: We borrowerd more than we lent | G2: 1.26 : 1
A3: Baldwin City Public Library | B3: 650 | C3: 449 | D3: 201 | E3: We borrowerd more than we lent | G3: 1.45 : 1
A4: Basehor Community Library | B4: 1313 | C4: 1120 | D4: 193 | E4: We borrowerd more than we lent | G4: 1.17 : 1
A5: Bern Community Library | B5: 12 | C5: 113 | D5: -101 | F5: We lent more than we borrowed | G5: 0.11 : 1
A6: Bonner Springs City Library | B6: 1061 | C6: 1170 | D6: -109 | F6: We lent more than we borrowed | G6: 0.91 : 1
A7: Burlingame Community Library | B7: 228 | C7: 188 | D7: 40 | E7: We borrowerd more than we lent | G7: 1.21 : 1
A8: Carbondale City Library | B8: 144 | C8: 165 | D8: -21 | F8: We lent more than we borrowed | G8: 0.87 : 1
A9: Centralia Community Library | B9: 45 | C9: 47 | D9: -2 | F9: We lent more than we borrowed | G9: 0.96 : 1
A10: Corning City Library | B10: 0 | C10: 26 | D10: -26 | F10: We lent more than we borrowed | G10: 0.00 : 1
A11: Digital Content | B11: 0 | C11: 0 | D11: 0
A12: Doniphan County Library - Elwood | B12: 3 | C12: 22 | D12: -19 | F12: We lent more than we borrowed | G12: 0.14 : 1
A13: Doniphan County Library - Highland | B13: 69 | C13: 58 | D13: 11 | E13: We borrowerd more than we lent | G13: 1.19 : 1
A14: Doniphan County Library - Troy | B14: 137 | C14: 334 | D14: -197 | F14: We lent more than we borrowed | G14: 0.41 : 1
A15: Doniphan County Library - Wathena | B15: 51 | C15: 135 | D15: -84 | F15: We lent more than we borrowed | G15: 0.38 : 1
A16: Effingham Community Library | B16: 53 | C16: 229 | D16: -176 | F16: We lent more than we borrowed | G16: 0.23 : 1
A17: Eudora Community Library | B17: 696 | C17: 429 | D17: 267 | E17: We borrowerd more than we lent | G17: 1.62 : 1
A18: Everest, Barnes Reading Room | B18: 73 | C18: 71 | D18: 2 | E18: We borrowerd more than we lent | G18: 1.03 : 1
A19: Hiawatha, Morrill Public Library | B19: 580 | C19: 348 | D19: 232 | E19: We borrowerd more than we lent | G19: 1.67 : 1
A20: Highland Community College | B20: 0 | C20: 55 | D20: -55 | F20: We lent more than we borrowed | G20: 0.00 : 1
A21: Holton, Beck-Bookman Library | B21: 563 | C21: 426 | D21: 137 | E21: We borrowerd more than we lent | G21: 1.32 : 1
A22: Horton Public Library | B22: 68 | C22: 240 | D22: -172 | F22: We lent more than we borrowed | G22: 0.28 : 1
A23: Lansing Community Library | B23: 860 | C23: 625 | D23: 235 | E23: We borrowerd more than we lent | G23: 1.38 : 1
A24: Leavenworth Public Library | B24: 1774 | C24: 1537 | D24: 237 | E24: We borrowerd more than we lent | G24: 1.15 : 1
A25: Linwood Community Library | B25: 117 | C25: 354 | D25: -237 | F25: We lent more than we borrowed | G25: 0.33 : 1
A26: Louisburg Library | B26: 0 | C26: 0 | D26: 0
A27: Lyndon Carnegie Library | B27: 169 | C27: 182 | D27: -13 | F27: We lent more than we borrowed | G27: 0.93 : 1
A28: McLouth Public Library | B28: 153 | C28: 138 | D28: 15 | E28: We borrowerd more than we lent | G28: 1.11 : 1
A29: Meriden-Ozawkie Public Library | B29: 800 | C29: 491 | D29: 309 | E29: We borrowerd more than we lent | G29: 1.63 : 1
A30: Northeast Kansas Library System | B30: 27 | C30: 15 | D30: 12 | E30: We borrowerd more than we lent | G30: 1.80 : 1
A31: Nortonville Public Library | B31: 146 | C31: 285 | D31: -139 | F31: We lent more than we borrowed | G31: 0.51 : 1
A32: Osage City Library | B32: 429 | C32: 609 | D32: -180 | F32: We lent more than we borrowed | G32: 0.70 : 1
A33: Osawatomie Public Library | B33: 386 | C33: 316 | D33: 70 | E33: We borrowerd more than we lent | G33: 1.22 : 1
A34: Oskaloosa Public Library | B34: 149 | C34: 157 | D34: -8 | F34: We lent more than we borrowed | G34: 0.95 : 1
A35: Ottawa Library | B35: 1059 | C35: 1616 | D35: -557 | F35: We lent more than we borrowed | G35: 0.66 : 1
A36: Overbrook Public Library | B36: 153 | C36: 570 | D36: -417 | F36: We lent more than we borrowed | G36: 0.27 : 1
A37: Paola Free Library | B37: 682 | C37: 465 | D37: 217 | E37: We borrowerd more than we lent | G37: 1.47 : 1
A38: Perry-Lecompton Community Library | B38: 33 | C38: 226 | D38: -193 | F38: We lent more than we borrowed | G38: 0.15 : 1
A39: Prairie Hills Schools - Axtell Public School | B39: 31 | C39: 103 | D39: -72 | F39: We lent more than we borrowed | G39: 0.30 : 1
A40: Prairie Hills Schools - Sabetha Elementary School | B40: 137 | C40: 142 | D40: -5 | F40: We lent more than we borrowed | G40: 0.96 : 1
...

Sheet April
A1: Library | B1: Other Next library materials checked out at our library | C1: Our materials checked out at other Next libraries | D1: NET | E1: Net borrower | F1: Net lender | G1: Borrowed to lent ratio
A2: Atchison Public Library | B2: 1453 | C2: 1233 | D2: 220 | E2: We borrowerd more than we lent | G2: 1.18 : 1
A3: Baldwin City Public Library | B3: 506 | C3: 457 | D3: 49 | E3: We borrowerd more than we lent | G3: 1.11 : 1
A4: Basehor Community Library | B4: 1036 | C4: 1118 | D4: -82 | F4: We lent more than we borrowed | G4: 0.93 : 1
A5: Bern Community Library | B5: 20 | C5: 105 | D5: -85 | F5: We lent more than we borrowed | G5: 0.19 : 1
A6: Bonner Springs City Library | B6: 905 | C6: 1050 | D6: -145 | F6: We lent more than we borrowed | G6: 0.86 : 1
A7: Burlingame Community Library | B7: 236 | C7: 168 | D7: 68 | E7: We borrowerd more than we lent | G7: 1.40 : 1
A8: Carbondale City Library | B8: 84 | C8: 162 | D8: -78 | F8: We lent more than we borrowed | G8: 0.52 : 1
A9: Centralia Community Library | B9: 44 | C9: 46 | D9: -2 | F9: We lent more than we borrowed | G9: 0.96 : 1
A10: Corning City Library | B10: 0 | C10: 21 | D10: -21 | F10: We lent more than we borrowed | G10: 0.00 : 1
A11: Digital Content | B11: 0 | C11: 0 | D11: 0
A12: Doniphan County Library - Elwood | B12: 11 | C12: 18 | D12: -7 | F12: We lent more than we borrowed | G12: 0.61 : 1
A13: Doniphan County Library - Highland | B13: 55 | C13: 48 | D13: 7 | E13: We borrowerd more than we lent | G13: 1.15 : 1
A14: Doniphan County Library - Troy | B14: 116 | C14: 293 | D14: -177 | F14: We lent more than we borrowed | G14: 0.40 : 1
A15: Doniphan County Library - Wathena | B15: 37 | C15: 125 | D15: -88 | F15: We lent more than we borrowed | G15: 0.30 : 1
A16: Effingham Community Library | B16: 72 | C16: 137 | D16: -65 | F16: We lent more than we borrowed | G16: 0.53 : 1
A17: Eudora Community Library | B17: 568 | C17: 460 | D17: 108 | E17: We borrowerd more than we lent | G17: 1.23 : 1
A18: Everest, Barnes Reading Room | B18: 123 | C18: 84 | D18: 39 | E18: We borrowerd more than we lent | G18: 1.46 : 1
A19: Hiawatha, Morrill Public Library | B19: 418 | C19: 303 | D19: 115 | E19: We borrowerd more than we lent | G19: 1.38 : 1
A20: Highland Community College | B20: 2 | C20: 33 | D20: -31 | F20: We lent more than we borrowed | G20: 0.06 : 1
A21: Holton, Beck-Bookman Library | B21: 446 | C21: 393 | D21: 53 | E21: We borrowerd more than we lent | G21: 1.13 : 1
A22: Horton Public Library | B22: 90 | C22: 205 | D22: -115 | F22: We lent more than we borrowed | G22: 0.44 : 1
A23: Lansing Community Library | B23: 634 | C23: 647 | D23: -13 | F23: We lent more than we borrowed | G23: 0.98 : 1
A24: Leavenworth Public Library | B24: 1819 | C24: 1318 | D24: 501 | E24: We borrowerd more than we lent | G24: 1.38 : 1
A25: Linwood Community Library | B25: 215 | C25: 324 | D25: -109 | F25: We lent more than we borrowed | G25: 0.66 : 1
A26: Louisburg Library | B26: 0 | C26: 0 | D26: 0
A27: Lyndon Carnegie Library | B27: 191 | C27: 119 | D27: 72 | E27: We borrowerd more than we lent | G27: 1.61 : 1
A28: McLouth Public Library | B28: 128 | C28: 94 | D28: 34 | E28: We borrowerd more than we lent | G28: 1.36 : 1
A29: Meriden-Ozawkie Public Library | B29: 776 | C29: 435 | D29: 341 | E29: We borrowerd more than we lent | G29: 1.78 : 1
A30: Northeast Kansas Library System | B30: 70 | C30: 18 | D30: 52 | E30: We borrowerd more than we lent | G30: 3.89 : 1
A31: Nortonville Public Library | B31: 101 | C31: 255 | D31: -154 | F31: We lent more than we borrowed | G31: 0.40 : 1
A32: Osage City Library | B32: 381 | C32: 475 | D32: -94 | F32: We lent more than we borrowed | G32: 0.80 : 1
A33: Osawatomie Public Library | B33: 310 | C33: 277 | D33: 33 | E33: We borrowerd more than we lent | G33: 1.12 : 1
A34: Oskaloosa Public Library | B34: 143 | C34: 91 | D34: 52 | E34: We borrowerd more than we lent | G34: 1.57 : 1
A35: Ottawa Library | B35: 1043 | C35: 1321 | D35: -278 | F35: We lent more than we borrowed | G35: 0.79 : 1
A36: Overbrook Public Library | B36: 175 | C36: 474 | D36: -299 | F36: We lent more than we borrowed | G36: 0.37 : 1
A37: Paola Free Library | B37: 628 | C37: 310 | D37: 318 | E37: We borrowerd more than we lent | G37: 2.03 : 1
A38: Perry-Lecompton Community Library | B38: 48 | C38: 192 | D38: -144 | F38: We lent more than we borrowed | G38: 0.25 : 1
A39: Prairie Hills Schools - Axtell Public School | B39: 11 | C39: 75 | D39: -64 | F39: We lent more than we borrowed | G39: 0.15 : 1
A40: Prairie Hills Schools - Sabetha Elementary School | B40: 97 | C40: 122 | D40: -25 | F40: We lent more than we borrowed | G40: 0.80 : 1
...

Sheet May
A1: Library | B1: Other Next library materials checked out at our library | C1: Our materials checked out at other Next libraries | D1: NET | E1: Net borrower | F1: Net lender | G1: Borrowed to lent ratio
A2: Atchison Public Library | B2: 1251 | C2: 970 | D2: 281 | E2: We borrowerd more than we lent | G2: 1.29 : 1
A3: Baldwin City Public Library | B3: 501 | C3: 401 | D3: 100 | E3: We borrowerd more than we lent | G3: 1.25 : 1
A4: Basehor Community Library | B4: 955 | C4: 1109 | D4: -154 | F4: We lent more than we borrowed | G4: 0.86 : 1
A5: Bern Community Library | B5: 19 | C5: 108 | D5: -89 | F5: We lent more than we borrowed | G5: 0.18 : 1
A6: Bonner Springs City Library | B6: 891 | C6: 1110 | D6: -219 | F6: We lent more than we borrowed | G6: 0.80 : 1
A7: Burlingame Community Library | B7: 409 | C7: 159 | D7: 250 | E7: We borrowerd more than we lent | G7: 2.57 : 1
A8: Carbondale City Library | B8: 87 | C8: 125 | D8: -38 | F8: We lent more than we borrowed | G8: 0.70 : 1
A9: Centralia Community Library | B9: 47 | C9: 40 | D9: 7 | E9: We borrowerd more than we lent | G9: 1.18 : 1
A10: Corning City Library | B10: 0 | C10: 10 | D10: -10 | F10: We lent more than we borrowed | G10: 0.00 : 1
A11: Digital Content | B11: 0 | C11: 0 | D11: 0
A12: Doniphan County Library - Elwood | B12: 4 | C12: 8 | D12: -4 | F12: We lent more than we borrowed | G12: 0.50 : 1
A13: Doniphan County Library - Highland | B13: 44 | C13: 44 | D13: 0 | G13: 1.00 : 1
A14: Doniphan County Library - Troy | B14: 97 | C14: 244 | D14: -147 | F14: We lent more than we borrowed | G14: 0.40 : 1
A15: Doniphan County Library - Wathena | B15: 30 | C15: 108 | D15: -78 | F15: We lent more than we borrowed | G15: 0.28 : 1
A16: Effingham Community Library | B16: 52 | C16: 106 | D16: -54 | F16: We lent more than we borrowed | G16: 0.49 : 1
A17: Eudora Community Library | B17: 557 | C17: 348 | D17: 209 | E17: We borrowerd more than we lent | G17: 1.60 : 1
A18: Everest, Barnes Reading Room | B18: 67 | C18: 72 | D18: -5 | F18: We lent more than we borrowed | G18: 0.93 : 1
A19: Hiawatha, Morrill Public Library | B19: 380 | C19: 348 | D19: 32 | E19: We borrowerd more than we lent | G19: 1.09 : 1
A20: Highland Community College | B20: 1 | C20: 34 | D20: -33 | F20: We lent more than we borrowed | G20: 0.03 : 1
A21: Holton, Beck-Bookman Library | B21: 510 | C21: 361 | D21: 149 | E21: We borrowerd more than we lent | G21: 1.41 : 1
A22: Horton Public Library | B22: 68 | C22: 184 | D22: -116 | F22: We lent more than we borrowed | G22: 0.37 : 1
A23: Lansing Community Library | B23: 479 | C23: 478 | D23: 1 | E23: We borrowerd more than we lent | G23: 1.00 : 1
A24: Leavenworth Public Library | B24: 1720 | C24: 1247 | D24: 473 | E24: We borrowerd more than we lent | G24: 1.38 : 1
A25: Linwood Community Library | B25: 123 | C25: 269 | D25: -146 | F25: We lent more than we borrowed | G25: 0.46 : 1
A26: Louisburg Library | B26: 0 | C26: 0 | D26: 0
A27: Lyndon Carnegie Library | B27: 225 | C27: 166 | D27: 59 | E27: We borrowerd more than we lent | G27: 1.36 : 1
A28: McLouth Public Library | B28: 170 | C28: 109 | D28: 61 | E28: We borrowerd more than we lent | G28: 1.56 : 1
A29: Meriden-Ozawkie Public Library | B29: 790 | C29: 327 | D29: 463 | E29: We borrowerd more than we lent | G29: 2.42 : 1
A30: Northeast Kansas Library System | B30: 25 | C30: 50 | D30: -25 | F30: We lent more than we borrowed | G30: 0.50 : 1
A31: Nortonville Public Library | B31: 92 | C31: 247 | D31: -155 | F31: We lent more than we borrowed | G31: 0.37 : 1
A32: Osage City Library | B32: 311 | C32: 457 | D32: -146 | F32: We lent more than we borrowed | G32: 0.68 : 1
A33: Osawatomie Public Library | B33: 295 | C33: 299 | D33: -4 | F33: We lent more than we borrowed | G33: 0.99 : 1
A34: Oskaloosa Public Library | B34: 143 | C34: 125 | D34: 18 | E34: We borrowerd more than we lent | G34: 1.14 : 1
A35: Ottawa Library | B35: 925 | C35: 1437 | D35: -512 | F35: We lent more than we borrowed | G35: 0.64 : 1
A36: Overbrook Public Library | B36: 160 | C36: 509 | D36: -349 | F36: We lent more than we borrowed | G36: 0.31 : 1
A37: Paola Free Library | B37: 521 | C37: 252 | D37: 269 | E37: We borrowerd more than we lent | G37: 2.07 : 1
A38: Perry-Lecompton Community Library | B38: 33 | C38: 223 | D38: -190 | F38: We lent more than we borrowed | G38: 0.15 : 1
A39: Prairie Hills Schools - Axtell Public School | B39: 0 | C39: 36 | D39: -36 | F39: We lent more than we borrowed | G39: 0.00 : 1
A40: Prairie Hills Schools - Sabetha Elementary School | B40: 4 | C40: 57 | D40: -53 | F40: We lent more than we borrowed | G40: 0.07 : 1
...

Sheet June
A1: Library | B1: Other Next library materials checked out at our library | C1: Our materials checked out at other Next libraries | D1: NET | E1: Net borrower | F1: Net lender | G1: Borrowed to lent ratio
A2: Atchison Public Library | B2: 1359 | C2: 973 | D2: 386 | E2: We borrowerd more than we lent | G2: 1.40 : 1
A3: Baldwin City Public Library | B3: 719 | C3: 361 | D3: 358 | E3: We borrowerd more than we lent | G3: 1.99 : 1
A4: Basehor Community Library | B4: 1254 | C4: 1047 | D4: 207 | E4: We borrowerd more than we lent | G4: 1.20 : 1
A5: Bern Community Library | B5: 36 | C5: 121 | D5: -85 | F5: We lent more than we borrowed | G5: 0.30 : 1
A6: Bonner Springs City Library | B6: 956 | C6: 999 | D6: -43 | F6: We lent more than we borrowed | G6: 0.96 : 1
A7: Burlingame Community Library | B7: 240 | C7: 190 | D7: 50 | E7: We borrowerd more than we lent | G7: 1.26 : 1
A8: Carbondale City Library | B8: 103 | C8: 159 | D8: -56 | F8: We lent more than we borrowed | G8: 0.65 : 1
A9: Centralia Community Library | B9: 68 | C9: 39 | D9: 29 | E9: We borrowerd more than we lent | G9: 1.74 : 1
A10: Corning City Library | B10: 0 | C10: 14 | D10: -14 | F10: We lent more than we borrowed | G10: 0.00 : 1
A11: Digital Content | B11: 0 | C11: 0 | D11: 0
A12: Doniphan County Library - Elwood | B12: 4 | C12: 24 | D12: -20 | F12: We lent more than we borrowed | G12: 0.17 : 1
A13: Doniphan County Library - Highland | B13: 27 | C13: 53 | D13: -26 | F13: We lent more than we borrowed | G13: 0.51 : 1
A14: Doniphan County Library - Troy | B14: 107 | C14: 295 | D14: -188 | F14: We lent more than we borrowed | G14: 0.36 : 1
A15: Doniphan County Library - Wathena | B15: 56 | C15: 135 | D15: -79 | F15: We lent more than we borrowed | G15: 0.41 : 1
A16: Effingham Community Library | B16: 53 | C16: 143 | D16: -90 | F16: We lent more than we borrowed | G16: 0.37 : 1
A17: Eudora Community Library | B17: 670 | C17: 416 | D17: 254 | E17: We borrowerd more than we lent | G17: 1.61 : 1
A18: Everest, Barnes Reading Room | B18: 77 | C18: 80 | D18: -3 | F18: We lent more than we borrowed | G18: 0.96 : 1
A19: Hiawatha, Morrill Public Library | B19: 400 | C19: 318 | D19: 82 | E19: We borrowerd more than we lent | G19: 1.26 : 1
A20: Highland Community College | B20: 1 | C20: 30 | D20: -29 | F20: We lent more than we borrowed | G20: 0.03 : 1
A21: Holton, Beck-Bookman Library | B21: 464 | C21: 339 | D21: 125 | E21: We borrowerd more than we lent | G21: 1.37 : 1
A22: Horton Public Library | B22: 79 | C22: 215 | D22: -136 | F22: We lent more than we borrowed | G22: 0.37 : 1
A23: Lansing Community Library | B23: 584 | C23: 655 | D23: -71 | F23: We lent more than we borrowed | G23: 0.89 : 1
A24: Leavenworth Public Library | B24: 1572 | C24: 1413 | D24: 159 | E24: We borrowerd more than we lent | G24: 1.11 : 1
A25: Linwood Community Library | B25: 151 | C25: 355 | D25: -204 | F25: We lent more than we borrowed | G25: 0.43 : 1
A26: Louisburg Library | B26: 0 | C26: 0 | D26: 0
A27: Lyndon Carnegie Library | B27: 225 | C27: 181 | D27: 44 | E27: We borrowerd more than we lent | G27: 1.24 : 1
A28: McLouth Public Library | B28: 160 | C28: 93 | D28: 67 | E28: We borrowerd more than we lent | G28: 1.72 : 1
A29: Meriden-Ozawkie Public Library | B29: 882 | C29: 447 | D29: 435 | E29: We borrowerd more than we lent | G29: 1.97 : 1
A30: Northeast Kansas Library System | B30: 20 | C30: 34 | D30: -14 | F30: We lent more than we borrowed | G30: 0.59 : 1
A31: Nortonville Public Library | B31: 94 | C31: 263 | D31: -169 | F31: We lent more than we borrowed | G31: 0.36 : 1
A32: Osage City Library | B32: 335 | C32: 497 | D32: -162 | F32: We lent more than we borrowed | G32: 0.67 : 1
A33: Osawatomie Public Library | B33: 348 | C33: 271 | D33: 77 | E33: We borrowerd more than we lent | G33: 1.28 : 1
A34: Oskaloosa Public Library | B34: 147 | C34: 121 | D34: 26 | E34: We borrowerd more than we lent | G34: 1.21 : 1
A35: Ottawa Library | B35: 1031 | C35: 1566 | D35: -535 | F35: We lent more than we borrowed | G35: 0.66 : 1
A36: Overbrook Public Library | B36: 176 | C36: 567 | D36: -391 | F36: We lent more than we borrowed | G36: 0.31 : 1
A37: Paola Free Library | B37: 550 | C37: 382 | D37: 168 | E37: We borrowerd more than we lent | G37: 1.44 : 1
A38: Perry-Lecompton Community Library | B38: 78 | C38: 228 | D38: -150 | F38: We lent more than we borrowed | G38: 0.34 : 1
A39: Prairie Hills Schools - Axtell Public School | B39: 0 | C39: 10 | D39: -10 | F39: We lent more than we borrowed | G39: 0.00 : 1
A40: Prairie Hills Schools - Sabetha Elementary School | B40: 0 | C40: 1 | D40: -1 | F40: We lent more than we borrowed | G40: 0.00 : 1
...

Sheet July
A1: Library | B1: Other Next library materials checked out at our library | C1: Our materials checked out at other Next libraries | D1: NET | E1: Net borrower | F1: Net lender | G1: Borrowed to lent ratio
A2: Atchison Public Library | B2: 1459 | C2: 1173 | D2: 286 | E2: We borrowerd more than we lent | G2: 1.24 : 1
A3: Baldwin City Public Library | B3: 771 | C3: 346 | D3: 425 | E3: We borrowerd more than we lent | G3: 2.23 : 1
A4: Basehor Community Library | B4: 1270 | C4: 1062 | D4: 208 | E4: We borrowerd more than we lent | G4: 1.20 : 1
A5: Bern Community Library | B5: 31 | C5: 105 | D5: -74 | F5: We lent more than we borrowed | G5: 0.30 : 1
A6: Bonner Springs City Library | B6: 920 | C6: 1082 | D6: -162 | F6: We lent more than we borrowed | G6: 0.85 : 1
A7: Burlingame Community Library | B7: 273 | C7: 169 | D7: 104 | E7: We borrowerd more than we lent | G7: 1.62 : 1
A8: Carbondale City Library | B8: 165 | C8: 138 | D8: 27 | E8: We borrowerd more than we lent | G8: 1.20 : 1
A9: Centralia Community Library | B9: 76 | C9: 64 | D9: 12 | E9: We borrowerd more than we lent | G9: 1.19 : 1
A10: Corning City Library | B10: 2 | C10: 22 | D10: -20 | F10: We lent more than we borrowed | G10: 0.09 : 1
A11: Digital Content | B11: 0 | C11: 0 | D11: 0
A12: Doniphan County Library - Elwood | B12: 8 | C12: 22 | D12: -14 | F12: We lent more than we borrowed | G12: 0.36 : 1
A13: Doniphan County Library - Highland | B13: 34 | C13: 59 | D13: -25 | F13: We lent more than we borrowed | G13: 0.58 : 1
A14: Doniphan County Library - Troy | B14: 116 | C14: 291 | D14: -175 | F14: We lent more than we borrowed | G14: 0.40 : 1
A15: Doniphan County Library - Wathena | B15: 52 | C15: 133 | D15: -81 | F15: We lent more than we borrowed | G15: 0.39 : 1
A16: Effingham Community Library | B16: 49 | C16: 141 | D16: -92 | F16: We lent more than we borrowed | G16: 0.35 : 1
A17: Eudora Community Library | B17: 613 | C17: 396 | D17: 217 | E17: We borrowerd more than we lent | G17: 1.55 : 1
A18: Everest, Barnes Reading Room | B18: 52 | C18: 96 | D18: -44 | F18: We lent more than we borrowed | G18: 0.54 : 1
A19: Hiawatha, Morrill Public Library | B19: 563 | C19: 348 | D19: 215 | E19: We borrowerd more than we lent | G19: 1.62 : 1
A20: Highland Community College | B20: 0 | C20: 43 | D20: -43 | F20: We lent more than we borrowed | G20: 0.00 : 1
A21: Holton, Beck-Bookman Library | B21: 549 | C21: 373 | D21: 176 | E21: We borrowerd more than we lent | G21: 1.47 : 1
A22: Horton Public Library | B22: 62 | C22: 231 | D22: -169 | F22: We lent more than we borrowed | G22: 0.27 : 1
A23: Lansing Community Library | B23: 738 | C23: 590 | D23: 148 | E23: We borrowerd more than we lent | G23: 1.25 : 1
A24: Leavenworth Public Library | B24: 1611 | C24: 1441 | D24: 170 | E24: We borrowerd more than we lent | G24: 1.12 : 1
A25: Linwood Community Library | B25: 103 | C25: 347 | D25: -244 | F25: We lent more than we borrowed | G25: 0.30 : 1
A26: Louisburg Library | B26: 0 | C26: 0 | D26: 0
A27: Lyndon Carnegie Library | B27: 235 | C27: 190 | D27: 45 | E27: We borrowerd more than we lent | G27: 1.24 : 1
A28: McLouth Public Library | B28: 183 | C28: 84 | D28: 99 | E28: We borrowerd more than we lent | G28: 2.18 : 1
A29: Meriden-Ozawkie Public Library | B29: 844 | C29: 471 | D29: 373 | E29: We borrowerd more than we lent | G29: 1.79 : 1
A30: Northeast Kansas Library System | B30: 88 | C30: 27 | D30: 61 | E30: We borrowerd more than we lent | G30: 3.26 : 1
A31: Nortonville Public Library | B31: 112 | C31: 337 | D31: -225 | F31: We lent more than we borrowed | G31: 0.33 : 1
A32: Osage City Library | B32: 449 | C32: 463 | D32: -14 | F32: We lent more than we borrowed | G32: 0.97 : 1
A33: Osawatomie Public Library | B33: 323 | C33: 334 | D33: -11 | F33: We lent more than we borrowed | G33: 0.97 : 1
A34: Oskaloosa Public Library | B34: 183 | C34: 122 | D34: 61 | E34: We borrowerd more than we lent | G34: 1.50 : 1
A35: Ottawa Library | B35: 1032 | C35: 1794 | D35: -762 | F35: We lent more than we borrowed | G35: 0.58 : 1
A36: Overbrook Public Library | B36: 177 | C36: 504 | D36: -327 | F36: We lent more than we borrowed | G36: 0.35 : 1
A37: Paola Free Library | B37: 646 | C37: 250 | D37: 396 | E37: We borrowerd more than we lent | G37: 2.58 : 1
A38: Perry-Lecompton Community Library | B38: 30 | C38: 227 | D38: -197 | F38: We lent more than we borrowed | G38: 0.13 : 1
A39: Prairie Hills Schools - Axtell Public School | B39: 0 | C39: 1 | D39: -1 | F39: We lent more than we borrowed | G39: 0.00 : 1
A40: Prairie Hills Schools - Sabetha Elementary School | B40: 0 | C40: 2 | D40: -2 | F40: We lent more than we borrowed | G40: 0.00 : 1
...

Sheet August
A1: Library | B1: Other Next library materials checked out at our library | C1: Our materials checked out at other Next libraries | D1: NET | E1: Net borrower | F1: Net lender | G1: Borrowed to lent ratio
A2: Atchison Public Library | B2: 1469 | C2: 1152 | D2: 317 | E2: We borrowerd more than we lent | G2: 1.28 : 1
A3: Baldwin City Public Library | B3: 633 | C3: 314 | D3: 319 | E3: We borrowerd more than we lent | G3: 2.02 : 1
A4: Basehor Community Library | B4: 1232 | C4: 1270 | D4: -38 | F4: We lent more than we borrowed | G4: 0.97 : 1
A5: Bern Community Library | B5: 31 | C5: 104 | D5: -73 | F5: We lent more than we borrowed | G5: 0.30 : 1
A6: Bonner Springs City Library | B6: 907 | C6: 1139 | D6: -232 | F6: We lent more than we borrowed | G6: 0.80 : 1
A7: Burlingame Community Library | B7: 256 | C7: 167 | D7: 89 | E7: We borrowerd more than we lent | G7: 1.53 : 1
A8: Carbondale City Library | B8: 128 | C8: 154 | D8: -26 | F8: We lent more than we borrowed | G8: 0.83 : 1
A9: Centralia Community Library | B9: 94 | C9: 47 | D9: 47 | E9: We borrowerd more than we lent | G9: 2.00 : 1
A10: Corning City Library | B10: 0 | C10: 26 | D10: -26 | F10: We lent more than we borrowed | G10: 0.00 : 1
A11: Digital Content | B11: 0 | C11: 0 | D11: 0
A12: Doniphan County Library - Elwood | B12: 2 | C12: 17 | D12: -15 | F12: We lent more than we borrowed | G12: 0.12 : 1
A13: Doniphan County Library - Highland | B13: 26 | C13: 64 | D13: -38 | F13: We lent more than we borrowed | G13: 0.41 : 1
A14: Doniphan County Library - Troy | B14: 112 | C14: 288 | D14: -176 | F14: We lent more than we borrowed | G14: 0.39 : 1
A15: Doniphan County Library - Wathena | B15: 52 | C15: 162 | D15: -110 | F15: We lent more than we borrowed | G15: 0.32 : 1
A16: Effingham Community Library | B16: 57 | C16: 156 | D16: -99 | F16: We lent more than we borrowed | G16: 0.37 : 1
A17: Eudora Community Library | B17: 720 | C17: 469 | D17: 251 | E17: We borrowerd more than we lent | G17: 1.54 : 1
A18: Everest, Barnes Reading Room | B18: 46 | C18: 92 | D18: -46 | F18: We lent more than we borrowed | G18: 0.50 : 1
A19: Hiawatha, Morrill Public Library | B19: 484 | C19: 299 | D19: 185 | E19: We borrowerd more than we lent | G19: 1.62 : 1
A20: Highland Community College | B20: 5 | C20: 31 | D20: -26 | F20: We lent more than we borrowed | G20: 0.16 : 1
A21: Holton, Beck-Bookman Library | B21: 495 | C21: 376 | D21: 119 | E21: We borrowerd more than we lent | G21: 1.32 : 1
A22: Horton Public Library | B22: 73 | C22: 244 | D22: -171 | F22: We lent more than we borrowed | G22: 0.30 : 1
A23: Lansing Community Library | B23: 797 | C23: 504 | D23: 293 | E23: We borrowerd more than we lent | G23: 1.58 : 1
A24: Leavenworth Public Library | B24: 1765 | C24: 1452 | D24: 313 | E24: We borrowerd more than we lent | G24: 1.22 : 1
A25: Linwood Community Library | B25: 160 | C25: 341 | D25: -181 | F25: We lent more than we borrowed | G25: 0.47 : 1
A26: Louisburg Library | B26: 0 | C26: 0 | D26: 0
A27: Lyndon Carnegie Library | B27: 191 | C27: 194 | D27: -3 | F27: We lent more than we borrowed | G27: 0.98 : 1
A28: McLouth Public Library | B28: 183 | C28: 113 | D28: 70 | E28: We borrowerd more than we lent | G28: 1.62 : 1
A29: Meriden-Ozawkie Public Library | B29: 714 | C29: 513 | D29: 201 | E29: We borrowerd more than we lent | G29: 1.39 : 1
A30: Northeast Kansas Library System | B30: 36 | C30: 48 | D30: -12 | F30: We lent more than we borrowed | G30: 0.75 : 1
A31: Nortonville Public Library | B31: 41 | C31: 316 | D31: -275 | F31: We lent more than we borrowed | G31: 0.13 : 1
A32: Osage City Library | B32: 439 | C32: 495 | D32: -56 | F32: We lent more than we borrowed | G32: 0.89 : 1
A33: Osawatomie Public Library | B33: 366 | C33: 417 | D33: -51 | F33: We lent more than we borrowed | G33: 0.88 : 1
A34: Oskaloosa Public Library | B34: 178 | C34: 147 | D34: 31 | E34: We borrowerd more than we lent | G34: 1.21 : 1
A35: Ottawa Library | B35: 1218 | C35: 1605 | D35: -387 | F35: We lent more than we borrowed | G35: 0.76 : 1
A36: Overbrook Public Library | B36: 173 | C36: 621 | D36: -448 | F36: We lent more than we borrowed | G36: 0.28 : 1
A37: Paola Free Library | B37: 597 | C37: 296 | D37: 301 | E37: We borrowerd more than we lent | G37: 2.02 : 1
A38: Perry-Lecompton Community Library | B38: 37 | C38: 192 | D38: -155 | F38: We lent more than we borrowed | G38: 0.19 : 1
A39: Prairie Hills Schools - Axtell Public School | B39: 4 | C39: 28 | D39: -24 | F39: We lent more than we borrowed | G39: 0.14 : 1
A40: Prairie Hills Schools - Sabetha Elementary School | B40: 2 | C40: 40 | D40: -38 | F40: We lent more than we borrowed | G40: 0.05 : 1
...

Sheet September
A1: Library | B1: Other Next library materials checked out at our library | C1: Our materials checked out at other Next libraries | D1: NET | E1: Net borrower | F1: Net lender | G1: Borrowed to lent ratio
A2: Atchison Public Library
A3: Baldwin City Public Library
A4: Basehor Community Library
A5: Bern Community Library
A6: Bonner Springs City Library
A7: Burlingame Community Library
A8: Carbondale City Library
A9: Centralia Community Library
A10: Corning City Library
A11: Digital Content
A12: Doniphan County Library - Elwood
A13: Doniphan County Library - Highland
... A54: Winchester Public Library

Sheet October
A1: Library | B1: Other Next library materials checked out at our library | C1: Our materials checked out at other Next libraries | D1: NET | E1: Net borrower | F1: Net lender | G1: Borrowed to lent ratio
A2: Atchison Public Library
A3: Baldwin City Public Library
A4: Basehor Community Library
A5: Bern Community Library
A6: Bonner Springs City Library
A7: Burlingame Community Library
A8: Carbondale City Library
A9: Centralia Community Library
A10: Corning City Library
A11: Digital Content
A12: Doniphan County Library - Elwood
A13: Doniphan County Library - Highland
... A54: Winchester Public Library

Sheet November
A1: Library | B1: Other Next library materials checked out at our library | C1: Our materials checked out at other Next libraries | D1: NET | E1: Net borrower | F1: Net lender | G1: Borrowed to lent ratio
A2: Atchison Public Library
A3: Baldwin City Public Library
A4: Basehor Community Library
A5: Bern Community Library
A6: Bonner Springs City Library
A7: Burlingame Community Library
A8: Carbondale City Library
A9: Centralia Community Library
A10: Corning City Library
A11: Digital Content
A12: Doniphan County Library - Elwood
A13: Doniphan County Library - Highland
... A54: Winchester Public Library

Sheet December
A1: Library | B1: Other Next library materials checked out at our library | C1: Our materials checked out at other Next libraries | D1: NET | E1: Net borrower | F1: Net lender | G1: Borrowed to lent ratio
A2: Atchison Public Library
A3: Baldwin City Public Library
A4: Basehor Community Library
A5: Bern Community Library
A6: Bonner Springs City Library
A7: Burlingame Community Library
A8: Carbondale City Library
A9: Centralia Community Library
A10: Corning City Library
A11: Digital Content
A12: Doniphan County Library - Elwood
A13: Doniphan County Library - Highland
... A54: Winchester Public Library

Sheet Yearly total
A1: Library | B1: Other Next library materials checked out at our library | C1: Our materials checked out at other Next libraries | D1: NET | E1: Net borrower | F1: Net lender | G1: Borrowed to lent ratio
A2: Atchison Public Library | B2: =January!B2+February!B2+March!B2+April!B2+May!B2+June!B2+July!B2+August!B2+September!B2+October!B2+November!B2+December!B2 -> 11394 | C2: =January!C2+February!C2+March!C2+April!C2+May!C2+June!C2+July!C2+August!C2+September!C2+October!C2+November!C2+December!C2 -> 9204 | D2: =January!D2+February!D2+March!D2+April!D2+May!D2+June!D2+July!D2+August!D2+September!D2+October!D2+November!D2+December!D2 -> 2190 | E2: =IF(D2 > 0, "We borrowed more than we lent this year", "") -> We borrowed more than we lent this year | F2: =IF(D2 < 0, "We lent more than we borrowed this year", "") | G2: =IF(ISERROR(ROUND(B2/C2,2)&" : 1"), "", ROUND(B2/C2,2)&" : 1") -> 1.24 : 1
A3: Baldwin City Public Library | B3: =January!B3+February!B3+March!B3+April!B3+May!B3+June!B3+July!B3+August!B3+September!B3+October!B3+November!B3+December!B3 -> 5123 | C3: =January!C3+February!C3+March!C3+April!C3+May!C3+June!C3+July!C3+August!C3+September!C3+October!C3+November!C3+December!C3 -> 3107 | D3: =January!D3+February!D3+March!D3+April!D3+May!D3+June!D3+July!D3+August!D3+September!D3+October!D3+November!D3+December!D3 -> 2016 | E3: =IF(D3 > 0, "We borrowed more than we lent this year", "") -> We borrowed more than we lent this year | F3: =IF(D3 < 0, "We lent more than we borrowed this year", "") | G3: =IF(ISERROR(ROUND(B3/C3,2)&" : 1"), "", ROUND(B3/C3,2)&" : 1") -> 1.65 : 1
A4: Basehor Community Library | B4: =January!B4+February!B4+March!B4+April!B4+May!B4+June!B4+July!B4+August!B4+September!B4+October!B4+November!B4+December!B4 -> 9569 | C4: =January!C4+February!C4+March!C4+April!C4+May!C4+June!C4+July!C4+August!C4+September!C4+October!C4+November!C4+December!C4 -> 9086 | D4: =January!D4+February!D4+March!D4+April!D4+May!D4+June!D4+July!D4+August!D4+September!D4+October!D4+November!D4+December!D4 -> 483 | E4: =IF(D4 > 0, "We borrowed more than we lent this year", "") -> We borrowed more than we lent this year | F4: =IF(D4 < 0, "We lent more than we borrowed this year", "") | G4: =IF(ISERROR(ROUND(B4/C4,2)&" : 1"), "", ROUND(B4/C4,2)&" : 1") -> 1.05 : 1
A5: Bern Community Library | B5: =January!B5+February!B5+March!B5+April!B5+May!B5+June!B5+July!B5+August!B5+September!B5+October!B5+November!B5+December!B5 -> 195 | C5: =January!C5+February!C5+March!C5+April!C5+May!C5+June!C5+July!C5+August!C5+September!C5+October!C5+November!C5+December!C5 -> 910 | D5: =January!D5+February!D5+March!D5+April!D5+May!D5+June!D5+July!D5+August!D5+September!D5+October!D5+November!D5+December!D5 -> -715 | E5: =IF(D5 > 0, "We borrowed more than we lent this year", "") | F5: =IF(D5 < 0, "We lent more than we borrowed this year", "") -> We lent more than we borrowed this year | G5: =IF(ISERROR(ROUND(B5/C5,2)&" : 1"), "", ROUND(B5/C5,2)&" : 1") -> 0.21 : 1
A6: Bonner Springs City Library | B6: =January!B6+February!B6+March!B6+April!B6+May!B6+June!B6+July!B6+August!B6+September!B6+October!B6+November!B6+December!B6 -> 7768 | C6: =January!C6+February!C6+March!C6+April!C6+May!C6+June!C6+July!C6+August!C6+September!C6+October!C6+November!C6+December!C6 -> 8834 | D6: =January!D6+February!D6+March!D6+April!D6+May!D6+June!D6+July!D6+August!D6+September!D6+October!D6+November!D6+December!D6 -> -1066 | E6: =IF(D6 > 0, "We borrowed more than we lent this year", "") | F6: =IF(D6 < 0, "We lent more than we borrowed this year", "") -> We lent more than we borrowed this year | G6: =IF(ISERROR(ROUND(B6/C6,2)&" : 1"), "", ROUND(B6/C6,2)&" : 1") -> 0.88 : 1
A7: Burlingame Community Library | B7: =January!B7+February!B7+March!B7+April!B7+May!B7+June!B7+July!B7+August!B7+September!B7+October!B7+November!B7+December!B7 -> 2028 | C7: =January!C7+February!C7+March!C7+April!C7+May!C7+June!C7+July!C7+August!C7+September!C7+October!C7+November!C7+December!C7 -> 1368 | D7: =January!D7+February!D7+March!D7+April!D7+May!D7+June!D7+July!D7+August!D7+September!D7+October!D7+November!D7+December!D7 -> 660 | E7: =IF(D7 > 0, "We borrowed more than we lent this year", "") -> We borrowed more than we lent this year | F7: =IF(D7 < 0, "We lent more than we borrowed this year", "") | G7: =IF(ISERROR(ROUND(B7/C7,2)&" : 1"), "", ROUND(B7/C7,2)&" : 1") -> 1.48 : 1
A8: Carbondale City Library | B8: =January!B8+February!B8+March!B8+April!B8+May!B8+June!B8+July!B8+August!B8+September!B8+October!B8+November!B8+December!B8 -> 929 | C8: =January!C8+February!C8+March!C8+April!C8+May!C8+June!C8+July!C8+August!C8+September!C8+October!C8+November!C8+December!C8 -> 1254 | D8: =January!D8+February!D8+March!D8+April!D8+May!D8+June!D8+July!D8+August!D8+September!D8+October!D8+November!D8+December!D8 -> -325 | E8: =IF(D8 > 0, "We borrowed more than we lent this year", "") | F8: =IF(D8 < 0, "We lent more than we borrowed this year", "") -> We lent more than we borrowed this year | G8: =IF(ISERROR(ROUND(B8/C8,2)&" : 1"), "", ROUND(B8/C8,2)&" : 1") -> 0.74 : 1
A9: Centralia Community Library | B9: =January!B9+February!B9+March!B9+April!B9+May!B9+June!B9+July!B9+August!B9+September!B9+October!B9+November!B9+December!B9 -> 514 | C9: =January!C9+February!C9+March!C9+April!C9+May!C9+June!C9+July!C9+August!C9+September!C9+October!C9+November!C9+December!C9 -> 398 | D9: =January!D9+February!D9+March!D9+April!D9+May!D9+June!D9+July!D9+August!D9+September!D9+October!D9+November!D9+December!D9 -> 116 | E9: =IF(D9 > 0, "We borrowed more than we lent this year", "") -> We borrowed more than we lent this year | F9: =IF(D9 < 0, "We lent more than we borrowed this year", "") | G9: =IF(ISERROR(ROUND(B9/C9,2)&" : 1"), "", ROUND(B9/C9,2)&" : 1") -> 1.29 : 1
A10: Corning City Library | B10: =January!B10+February!B10+March!B10+April!B10+May!B10+June!B10+July!B10+August!B10+September!B10+October!B10+November!B10+December!B10 -> 5 | C10: =January!C10+February!C10+March!C10+April!C10+May!C10+June!C10+July!C10+August!C10+September!C10+October!C10+November!C10+December!C10 -> 169 | D10: =January!D10+February!D10+March!D10+April!D10+May!D10+June!D10+July!D10+August!D10+September!D10+October!D10+November!D10+December!D10 -> -164 | E10: =IF(D10 > 0, "We borrowed more than we lent this year", "") | F10: =IF(D10 < 0, "We lent more than we borrowed this year", "") -> We lent more than we borrowed this year | G10: =IF(ISERROR(ROUND(B10/C10,2)&" : 1"), "", ROUND(B10/C10,2)&" : 1") -> 0.03 : 1
A11: Digital Content | B11: =January!B11+February!B11+March!B11+April!B11+May!B11+June!B11+July!B11+August!B11+September!B11+October!B11+November!B11+December!B11 -> 0 | C11: =January!C11+February!C11+March!C11+April!C11+May!C11+June!C11+July!C11+August!C11+September!C11+October!C11+November!C11+December!C11 -> 0 | D11: =January!D11+February!D11+March!D11+April!D11+May!D11+June!D11+July!D11+August!D11+September!D11+October!D11+November!D11+December!D11 -> 0 | E11: =IF(D11 > 0, "We borrowed more than we lent this year", "") | F11: =IF(D11 < 0, "We lent more than we borrowed this year", "") | G11: =IF(ISERROR(ROUND(B11/C11,2)&" : 1"), "", ROUND(B11/C11,2)&" : 1")
A12: Doniphan County Library - Elwood | B12: =January!B12+February!B12+March!B12+April!B12+May!B12+June!B12+July!B12+August!B12+September!B12+October!B12+November!B12+December!B12 -> 41 | C12: =January!C12+February!C12+March!C12+April!C12+May!C12+June!C12+July!C12+August!C12+September!C12+October!C12+November!C12+December!C12 -> 154 | D12: =January!D12+February!D12+March!D12+April!D12+May!D12+June!D12+July!D12+August!D12+September!D12+October!D12+November!D12+December!D12 -> -113 | E12: =IF(D12 > 0, "We borrowed more than we lent this year", "") | F12: =IF(D12 < 0, "We lent more than we borrowed this year", "") -> We lent more than we borrowed this year | G12: =IF(ISERROR(ROUND(B12/C12,2)&" : 1"), "", ROUND(B12/C12,2)&" : 1") -> 0.27 : 1
A13: Doniphan County Library - Highland | B13: =January!B13+February!B13+March!B13+April!B13+May!B13+June!B13+July!B13+August!B13+September!B13+October!B13+November!B13+December!B13 -> 349 | C13: =January!C13+February!C13+March!C13+April!C13+May!C13+June!C13+July!C13+August!C13+September!C13+October!C13+November!C13+December!C13 -> 460 | D13: =January!D13+February!D13+March!D13+April!D13+May!D13+June!D13+July!D13+August!D13+September!D13+October!D13+November!D13+December!D13 -> -111 | E13: =IF(D13 > 0, "We borrowed more than we lent this year", "") | F13: =IF(D13 < 0, "We lent more than we borrowed this year", "") -> We lent more than we borrowed this year | G13: =IF(ISERROR(ROUND(B13/C13,2)&" : 1"), "", ROUND(B13/C13,2)&" : 1") -> 0.76 : 1
... A54: Winchester Public Library | B54: =January!B54+February!B54+March!B54+April!B54+May!B54+June!B54+July!B54+August!B54+September!B54+October!B54+November!B54+December!B54 -> 3069 | C54: =January!C54+February!C54+March!C54+April!C54+May!C54+June!C54+July!C54+August!C54+September!C54+October!C54+November!C54+December!C54 -> 1711 | D54: =January!D54+February!D54+March!D54+April!D54+May!D54+June!D54+July!D54+August!D54+September!D54+October!D54+November!D54+December!D54 -> 1358 | E54: =IF(D54 > 0, "We borrowed more than we lent this year", "") -> We borrowed more than we lent this year | F54: =IF(D54 < 0, "We lent more than we borrowed this year", "") | G54: =IF(ISERROR(ROUND(B54/C54,2)&" : 1"), "", ROUND(B54/C54,2)&" : 1") -> 1.79 : 1
