Workbook

Sheet January
A1: Library | B1: Items owned by this library checked out at this library this month | C1: Items owned by other libraries checked out at this library this month | D1: Total circulation this month
A2: Atchison Public Library | B2: 4222 | C2: 1441 | D2: 5663
A3: Baldwin City Public Library | B3: 2584 | C3: 671 | D3: 3255
A4: Basehor Community Library | B4: 7786 | C4: 1369 | D4: 9155
A5: Bern Community Library | B5: 61 | C5: 28 | D5: 89
A6: Bonner Springs City Library | B6: 5110 | C6: 1162 | D6: 6272
A7: Burlingame Community Library | B7: 845 | C7: 217 | D7: 1062
A8: Carbondale City Library | B8: 374 | C8: 111 | D8: 485
A9: Centralia Community Library | B9: 178 | C9: 73 | D9: 251
A10: Corning City Library | B10: 53 | D10: 53
A11: Digital Content
A12: Doniphan County Library - Elwood | B12: 21 | C12: 7 | D12: 28
A13: Doniphan County Library - Highland | B13: 108 | C13: 42 | D13: 150
A14: Doniphan County Library - Troy | B14: 577 | C14: 168 | D14: 745
A15: Doniphan County Library - Wathena | B15: 315 | C15: 55 | D15: 370
A16: Effingham Community Library | B16: 172 | C16: 74 | D16: 246
A17: Eudora Community Library | B17: 1204 | C17: 694 | D17: 1898
A18: Everest, Barnes Reading Room | B18: 90 | C18: 89 | D18: 179
A19: Hiawatha, Morrill Public Library | B19: 1547 | C19: 485 | D19: 2032
A20: Highland Community College | B20: 24 | C20: 3 | D20: 27
A21: Holton, Beck-Bookman Library | B21: 1517 | C21: 501 | D21: 2018
A22: Horton Public Library | B22: 223 | C22: 90 | D22: 313
A23: Lansing Community Library | B23: 1917 | C23: 613 | D23: 2530
... A25: Linwood Community Library | B25: 406 | C25: 172 | D25: 578
A26: Louisburg Library
A27: Lyndon Carnegie Library | B27: 410 | C27: 231 | D27: 641
A28: McLouth Public Library | B28: 327 | C28: 132 | D28: 459
A29: Meriden-Ozawkie Public Library | B29: 1689 | C29: 891 | D29: 2580
A30: Northeast Kansas Library System | B30: 13 | C30: 24 | D30: 37
A31: Nortonville Public Library | B31: 375 | C31: 119 | D31: 494
A32: Osage City Library | B32: 1269 | C32: 521 | D32: 1790
A33: Osawatomie Public Library | B33: 688 | C33: 373 | D33: 1061
A34: Oskaloosa Public Library | B34: 437 | C34: 208 | D34: 645
A35: Ottawa Library | B35: 5970 | C35: 925 | D35: 6895
A36: Overbrook Public Library | B36: 799 | C36: 180 | D36: 979
A37: Paola Free Library | B37: 2797 | C37: 493 | D37: 3290
A38: Perry-Lecompton Community Library | B38: 168 | C38: 19 | D38: 187
... A54: Winchester Public Library | B54: 314 | C54: 318 | D54: 632
A55: Doniphan County Library - total | B55: =SUM(B12,B13,B14,B15) -> 1021 | C55: =SUM(C12,C13,C14,C15) -> 272 | D55: =SUM(D12,D13,D14,D15) -> 1293
A56: Prairie Hills Schools - total | B56: =SUM(B40,B41,B42,B43) -> 3011 | C56: =SUM(C40,C41,C42,C43) -> 118 | D56: =SUM(D40,D41,D42,D43) -> 3129

Sheet February
A1: Library | B1: Items owned by this library checked out at this library this month | C1: Items owned by other libraries checked out at this library this month | D1: Total circulation this month
A2: Atchison Public Library | B2: 3756 | C2: 1366 | D2: 5122
A3: Baldwin City Public Library | B3: 2394 | C3: 672 | D3: 3066
A4: Basehor Community Library | B4: 6924 | C4: 1140 | D4: 8064
A5: Bern Community Library | B5: 84 | C5: 18 | D5: 102
A6: Bonner Springs City Library | B6: 4684 | C6: 966 | D6: 5650
A7: Burlingame Community Library | B7: 728 | C7: 169 | D7: 897
A8: Carbondale City Library | B8: 491 | C8: 107 | D8: 598
A9: Centralia Community Library | B9: 158 | C9: 67 | D9: 225
A10: Corning City Library | B10: 41 | C10: 3 | D10: 44
A11: Digital Content
A12: Doniphan County Library - Elwood | B12: 16 | C12: 2 | D12: 18
A13: Doniphan County Library - Highland | B13: 73 | C13: 52 | D13: 125
A14: Doniphan County Library - Troy | B14: 596 | C14: 126 | D14: 722
A15: Doniphan County Library - Wathena | B15: 180 | C15: 46 | D15: 226
A16: Effingham Community Library | B16: 234 | C16: 60 | D16: 294
A17: Eudora Community Library | B17: 1070 | C17: 728 | D17: 1798
A18: Everest, Barnes Reading Room | B18: 91 | C18: 114 | D18: 205
A19: Hiawatha, Morrill Public Library | B19: 1622 | C19: 724 | D19: 2346
A20: Highland Community College | B20: 28 | C20: 4 | D20: 32
A21: Holton, Beck-Bookman Library | B21: 1349 | C21: 448 | D21: 1797
A22: Horton Public Library | B22: 199 | C22: 129 | D22: 328
A23: Lansing Community Library | B23: 1932 | C23: 581 | D23: 2513
... A25: Linwood Community Library | B25: 391 | C25: 174 | D25: 565
A26: Louisburg Library
A27: Lyndon Carnegie Library | B27: 351 | C27: 172 | D27: 523
A28: McLouth Public Library | B28: 316 | C28: 126 | D28: 442
A29: Meriden-Ozawkie Public Library | B29: 1506 | C29: 870 | D29: 2376
A30: Northeast Kansas Library System | B30: 21 | C30: 9 | D30: 30
A31: Nortonville Public Library | B31: 332 | C31: 139 | D31: 471
A32: Osage City Library | B32: 1118 | C32: 399 | D32: 1517
A33: Osawatomie Public Library | B33: 757 | C33: 384 | D33: 1141
A34: Oskaloosa Public Library | B34: 591 | C34: 224 | D34: 815
A35: Ottawa Library | B35: 5478 | C35: 931 | D35: 6409
A36: Overbrook Public Library | B36: 734 | C36: 182 | D36: 916
A37: Paola Free Library | B37: 2758 | C37: 534 | D37: 3292
A38: Perry-Lecompton Community Library | B38: 160 | C38: 34 | D38: 194
... A54: Winchester Public Library | B54: 234 | C54: 438 | D54: 672
A55: Doniphan County Library - total | B55: =SUM(B12,B13,B14,B15) -> 865 | C55: =SUM(C12,C13,C14,C15) -> 226 | D55: =SUM(D12,D13,D14,D15) -> 1091
A56: Prairie Hills Schools - total | B56: =SUM(B40,B41,B42,B43) -> 3136 | C56: =SUM(C40,C41,C42,C43) -> 165 | D56: =SUM(D40,D41,D42,D43) -> 3301

Sheet March
A1: Library | B1: Items owned by this library checked out at this library this month | C1: Items owned by other libraries checked out at this library this month | D1: Total circulation this month
A2: Atchison Public Library | B2: 4244 | C2: 1596 | D2: 5840
A3: Baldwin City Public Library | B3: 2753 | C3: 650 | D3: 3403
A4: Basehor Community Library | B4: 8174 | C4: 1313 | D4: 9487
A5: Bern Community Library | B5: 75 | C5: 12 | D5: 87
A6: Bonner Springs City Library | B6: 5229 | C6: 1061 | D6: 6290
A7: Burlingame Community Library | B7: 481 | C7: 228 | D7: 709
A8: Carbondale City Library | B8: 411 | C8: 144 | D8: 555
A9: Centralia Community Library | B9: 181 | C9: 45 | D9: 226
A10: Corning City Library | B10: 46 | D10: 46
A11: Digital Content
A12: Doniphan County Library - Elwood | B12: 13 | C12: 3 | D12: 16
A13: Doniphan County Library - Highland | B13: 145 | C13: 69 | D13: 214
A14: Doniphan County Library - Troy | B14: 672 | C14: 137 | D14: 809
A15: Doniphan County Library - Wathena | B15: 277 | C15: 51 | D15: 328
A16: Effingham Community Library | B16: 251 | C16: 53 | D16: 304
A17: Eudora Community Library | B17: 1338 | C17: 696 | D17: 2034
A18: Everest, Barnes Reading Room | B18: 104 | C18: 73 | D18: 177
A19: Hiawatha, Morrill Public Library | B19: 1453 | C19: 580 | D19: 2033
A20: Highland Community College | B20: 39 | D20: 39
A21: Holton, Beck-Bookman Library | B21: 1591 | C21: 563 | D21: 2154
A22: Horton Public Library | B22: 268 | C22: 68 | D22: 336
A23: Lansing Community Library | B23: 2373 | C23: 860 | D23: 3233
A24: Leavenworth Public Library | B24: 10303 | C24: 1774 | D24: 12077
A25: Linwood Community Library | B25: 420 | C25: 117 | D25: 537
A26: Louisburg Library
A27: Lyndon Carnegie Library | B27: 450 | C27: 169 | D27: 619
A28: McLouth Public Library | B28: 316 | C28: 153 | D28: 469
A29: Meriden-Ozawkie Public Library | B29: 1748 | C29: 800 | D29: 2548
A30: Northeast Kansas Library System | B30: 4 | C30: 27 | D30: 31
A31: Nortonville Public Library | B31: 335 | C31: 146 | D31: 481
A32: Osage City Library | B32: 1217 | C32: 429 | D32: 1646
A33: Osawatomie Public Library | B33: 806 | C33: 386 | D33: 1192
A34: Oskaloosa Public Library | B34: 339 | C34: 149 | D34: 488
A35: Ottawa Library | B35: 5017 | C35: 1059 | D35: 6076
A36: Overbrook Public Library | B36: 722 | C36: 153 | D36: 875
A37: Paola Free Library | B37: 3172 | C37: 682 | D37: 3854
A38: Perry-Lecompton Community Library | B38: 200 | C38: 33 | D38: 233
... A54: Winchester Public Library | B54: 278 | C54: 448 | D54: 726
A55: Doniphan County Library - total | B55: =SUM(B12,B13,B14,B15) -> 1107 | C55: =SUM(C12,C13,C14,C15) -> 260 | D55: =SUM(D12,D13,D14,D15) -> 1367
...

Sheet April
A1: Library | B1: Items owned by this library checked out at this library this month | C1: Items owned by other libraries checked out at this library this month | D1: Total circulation this month
A2: Atchison Public Library | B2: 3801 | C2: 1453 | D2: 5254
A3: Baldwin City Public Library | B3: 2325 | C3: 506 | D3: 2831
A4: Basehor Community Library | B4: 7069 | C4: 1036 | D4: 8105
A5: Bern Community Library | B5: 107 | C5: 20 | D5: 127
A6: Bonner Springs City Library | B6: 5060 | C6: 905 | D6: 5965
A7: Burlingame Community Library | B7: 775 | C7: 236 | D7: 1011
A8: Carbondale City Library | B8: 318 | C8: 84 | D8: 402
A9: Centralia Community Library | B9: 188 | C9: 44 | D9: 232
A10: Corning City Library | B10: 59 | D10: 59
A11: Digital Content
A12: Doniphan County Library - Elwood | B12: 46 | C12: 11 | D12: 57
A13: Doniphan County Library - Highland | B13: 154 | C13: 55 | D13: 209
A14: Doniphan County Library - Troy | B14: 569 | C14: 116 | D14: 685
A15: Doniphan County Library - Wathena | B15: 242 | C15: 37 | D15: 279
A16: Effingham Community Library | B16: 255 | C16: 72 | D16: 327
A17: Eudora Community Library | B17: 1096 | C17: 568 | D17: 1664
A18: Everest, Barnes Reading Room | B18: 80 | C18: 123 | D18: 203
A19: Hiawatha, Morrill Public Library | B19: 1580 | C19: 418 | D19: 1998
A20: Highland Community College | B20: 18 | C20: 2 | D20: 20
A21: Holton, Beck-Bookman Library | B21: 1431 | C21: 446 | D21: 1877
A22: Horton Public Library | B22: 284 | C22: 90 | D22: 374
A23: Lansing Community Library | B23: 2337 | C23: 634 | D23: 2971
... A25: Linwood Community Library | B25: 389 | C25: 215 | D25: 604
A26: Louisburg Library
A27: Lyndon Carnegie Library | B27: 408 | C27: 191 | D27: 599
A28: McLouth Public Library | B28: 259 | C28: 128 | D28: 387
A29: Meriden-Ozawkie Public Library | B29: 1994 | C29: 776 | D29: 2770
A30: Northeast Kansas Library System | B30: 15 | C30: 70 | D30: 85
A31: Nortonville Public Library | B31: 292 | C31: 101 | D31: 393
A32: Osage City Library | B32: 1137 | C32: 381 | D32: 1518
A33: Osawatomie Public Library | B33: 736 | C33: 310 | D33: 1046
A34: Oskaloosa Public Library | B34: 401 | C34: 143 | D34: 544
A35: Ottawa Library | B35: 2522 | C35: 1043 | D35: 3565
A36: Overbrook Public Library | B36: 646 | C36: 175 | D36: 821
A37: Paola Free Library | B37: 2757 | C37: 628 | D37: 3385
A38: Perry-Lecompton Community Library | B38: 249 | C38: 48 | D38: 297
... A54: Winchester Public Library | B54: 224 | C54: 479 | D54: 703
A55: Doniphan County Library - total | B55: =SUM(B12,B13,B14,B15) -> 1011 | C55: =SUM(C12,C13,C14,C15) -> 219 | D55: =SUM(D12,D13,D14,D15) -> 1230
A56: Prairie Hills Schools - total | B56: =SUM(B40,B41,B42,B43) -> 2698 | C56: =SUM(C40,C41,C42,C43) -> 127 | D56: =SUM(D40,D41,D42,D43) -> 2825

Sheet May
A1: Library | B1: Items owned by this library checked out at this library this month | C1: Items owned by other libraries checked out at this library this month | D1: Total circulation this month
A2: Atchison Public Library | B2: 4694 | C2: 1251 | D2: 5945
A3: Baldwin City Public Library | B3: 3114 | C3: 501 | D3: 3615
A4: Basehor Community Library | B4: 7262 | C4: 955 | D4: 8217
A5: Bern Community Library | B5: 151 | C5: 19 | D5: 170
A6: Bonner Springs City Library | B6: 5368 | C6: 891 | D6: 6259
A7: Burlingame Community Library | B7: 534 | C7: 409 | D7: 943
A8: Carbondale City Library | B8: 447 | C8: 87 | D8: 534
A9: Centralia Community Library | B9: 244 | C9: 47 | D9: 291
A10: Corning City Library | B10: 30 | D10: 30
A11: Digital Content
A12: Doniphan County Library - Elwood | B12: 59 | C12: 4 | D12: 63
A13: Doniphan County Library - Highland | B13: 140 | C13: 44 | D13: 184
A14: Doniphan County Library - Troy | B14: 597 | C14: 97 | D14: 694
A15: Doniphan County Library - Wathena | B15: 255 | C15: 30 | D15: 285
A16: Effingham Community Library | B16: 209 | C16: 52 | D16: 261
A17: Eudora Community Library | B17: 1397 | C17: 557 | D17: 1954
A18: Everest, Barnes Reading Room | B18: 98 | C18: 67 | D18: 165
A19: Hiawatha, Morrill Public Library | B19: 1654 | C19: 380 | D19: 2034
A20: Highland Community College | B20: 7 | C20: 1 | D20: 8
A21: Holton, Beck-Bookman Library | B21: 1618 | C21: 510 | D21: 2128
A22: Horton Public Library | B22: 284 | C22: 68 | D22: 352
A23: Lansing Community Library | B23: 1367 | C23: 479 | D23: 1846
... A25: Linwood Community Library | B25: 499 | C25: 123 | D25: 622
A26: Louisburg Library
A27: Lyndon Carnegie Library | B27: 451 | C27: 225 | D27: 676
A28: McLouth Public Library | B28: 301 | C28: 170 | D28: 471
A29: Meriden-Ozawkie Public Library | B29: 2383 | C29: 790 | D29: 3173
A30: Northeast Kansas Library System | B30: 9 | C30: 25 | D30: 34
A31: Nortonville Public Library | B31: 326 | C31: 92 | D31: 418
A32: Osage City Library | B32: 1384 | C32: 311 | D32: 1695
A33: Osawatomie Public Library | B33: 906 | C33: 295 | D33: 1201
A34: Oskaloosa Public Library | B34: 510 | C34: 143 | D34: 653
A35: Ottawa Library | B35: 4558 | C35: 925 | D35: 5483
A36: Overbrook Public Library | B36: 801 | C36: 160 | D36: 961
A37: Paola Free Library | B37: 3559 | C37: 521 | D37: 4080
A38: Perry-Lecompton Community Library | B38: 327 | C38: 33 | D38: 360
A39: Pomona Community Library | B39: 77 | C39: 139 | D39: 216
A40: Prairie Hills Schools - Axtell Public School | B40: 102 | D40: 102
A41: Prairie Hills Schools - Sabetha Elementary School | B41: 22 | C41: 4 | D41: 26
...

Sheet June
A1: Library | B1: Items owned by this library checked out at this library this month | C1: Items owned by other libraries checked out at this library this month | D1: Total circulation this month
A2: Atchison Public Library | B2: 5522 | C2: 1359 | D2: 6881
A3: Baldwin City Public Library | B3: 3453 | C3: 719 | D3: 4172
A4: Basehor Community Library | B4: 9323 | C4: 1254 | D4: 10577
A5: Bern Community Library | B5: 388 | C5: 36 | D5: 424
A6: Bonner Springs City Library | B6: 6655 | C6: 956 | D6: 7611
A7: Burlingame Community Library | B7: 393 | C7: 240 | D7: 633
A8: Carbondale City Library | B8: 532 | C8: 103 | D8: 635
A9: Centralia Community Library | B9: 348 | C9: 68 | D9: 416
A10: Corning City Library | B10: 85 | D10: 85
A11: Digital Content
A12: Doniphan County Library - Elwood | B12: 33 | C12: 4 | D12: 37
A13: Doniphan County Library - Highland | B13: 163 | C13: 27 | D13: 190
A14: Doniphan County Library - Troy | B14: 598 | C14: 107 | D14: 705
A15: Doniphan County Library - Wathena | B15: 380 | C15: 56 | D15: 436
A16: Effingham Community Library | B16: 310 | C16: 53 | D16: 363
A17: Eudora Community Library | B17: 2105 | C17: 670 | D17: 2775
A18: Everest, Barnes Reading Room | B18: 109 | C18: 77 | D18: 186
A19: Hiawatha, Morrill Public Library | B19: 2149 | C19: 400 | D19: 2549
A20: Highland Community College | B20: 3 | C20: 1 | D20: 4
A21: Holton, Beck-Bookman Library | B21: 1931 | C21: 464 | D21: 2395
A22: Horton Public Library | B22: 416 | C22: 79 | D22: 495
A23: Lansing Community Library | B23: 2874 | C23: 584 | D23: 3458
... A25: Linwood Community Library | B25: 571 | C25: 151 | D25: 722
A26: Louisburg Library
A27: Lyndon Carnegie Library | B27: 651 | C27: 225 | D27: 876
A28: McLouth Public Library | B28: 472 | C28: 160 | D28: 632
A29: Meriden-Ozawkie Public Library | B29: 3100 | C29: 882 | D29: 3982
A30: Northeast Kansas Library System | B30: 7 | C30: 20 | D30: 27
A31: Nortonville Public Library | B31: 266 | C31: 94 | D31: 360
A32: Osage City Library | B32: 1837 | C32: 335 | D32: 2172
A33: Osawatomie Public Library | B33: 1540 | C33: 348 | D33: 1888
A34: Oskaloosa Public Library | B34: 563 | C34: 147 | D34: 710
A35: Ottawa Library | B35: 8782 | C35: 1031 | D35: 9813
A36: Overbrook Public Library | B36: 1035 | C36: 176 | D36: 1211
A37: Paola Free Library | B37: 4544 | C37: 550 | D37: 5094
A38: Perry-Lecompton Community Library | B38: 574 | C38: 78 | D38: 652
A39: Pomona Community Library | B39: 174 | C39: 40 | D39: 214
A40: Prairie Hills Schools - Axtell Public School
A41: Prairie Hills Schools - Sabetha Elementary School
...

Sheet July
A1: Library | B1: Items owned by this library checked out at this library this month | C1: Items owned by other libraries checked out at this library this month | D1: Total circulation this month
A2: Atchison Public Library | B2: 5138 | C2: 1459 | D2: 6597
A3: Baldwin City Public Library | B3: 3443 | C3: 771 | D3: 4214
A4: Basehor Community Library | B4: 8694 | C4: 1270 | D4: 9964
A5: Bern Community Library | B5: 250 | C5: 31 | D5: 281
A6: Bonner Springs City Library | B6: 6787 | C6: 920 | D6: 7707
A7: Burlingame Community Library | B7: 447 | C7: 273 | D7: 720
A8: Carbondale City Library | B8: 406 | C8: 165 | D8: 571
A9: Centralia Community Library | B9: 400 | C9: 76 | D9: 476
A10: Corning City Library | B10: 63 | C10: 2 | D10: 65
A11: Digital Content
A12: Doniphan County Library - Elwood | B12: 44 | C12: 8 | D12: 52
A13: Doniphan County Library - Highland | B13: 138 | C13: 34 | D13: 172
A14: Doniphan County Library - Troy | B14: 624 | C14: 116 | D14: 740
A15: Doniphan County Library - Wathena | B15: 328 | C15: 52 | D15: 380
A16: Effingham Community Library | B16: 282 | C16: 49 | D16: 331
A17: Eudora Community Library | B17: 1853 | C17: 613 | D17: 2466
A18: Everest, Barnes Reading Room | B18: 133 | C18: 52 | D18: 185
A19: Hiawatha, Morrill Public Library | B19: 2116 | C19: 563 | D19: 2679
A20: Highland Community College | B20: 12 | D20: 12
A21: Holton, Beck-Bookman Library | B21: 1697 | C21: 549 | D21: 2246
A22: Horton Public Library | B22: 372 | C22: 62 | D22: 434
A23: Lansing Community Library | B23: 3007 | C23: 738 | D23: 3745
A24: Leavenworth Public Library | B24: 12456 | C24: 1611 | D24: 14067
A25: Linwood Community Library | B25: 476 | C25: 103 | D25: 579
A26: Louisburg Library
A27: Lyndon Carnegie Library | B27: 520 | C27: 235 | D27: 755
A28: McLouth Public Library | B28: 345 | C28: 183 | D28: 528
A29: Meriden-Ozawkie Public Library | B29: 2595 | C29: 844 | D29: 3439
A30: Northeast Kansas Library System | B30: 16 | C30: 88 | D30: 104
A31: Nortonville Public Library | B31: 206 | C31: 112 | D31: 318
A32: Osage City Library | B32: 1611 | C32: 449 | D32: 2060
A33: Osawatomie Public Library | B33: 1195 | C33: 323 | D33: 1518
A34: Oskaloosa Public Library | B34: 635 | C34: 183 | D34: 818
A35: Ottawa Library | B35: 7295 | C35: 1032 | D35: 8327
A36: Overbrook Public Library | B36: 913 | C36: 177 | D36: 1090
A37: Paola Free Library | B37: 4225 | C37: 646 | D37: 4871
A38: Perry-Lecompton Community Library | B38: 404 | C38: 30 | D38: 434
A39: Pomona Community Library | B39: 107 | C39: 129 | D39: 236
A40: Prairie Hills Schools - Axtell Public School
...

Sheet August
A1: Library | B1: Items owned by this library checked out at this library this month | C1: Items owned by other libraries checked out at this library this month | D1: Total circulation this month
A2: Atchison Public Library | B2: 4404 | C2: 1469 | D2: 5873
A3: Baldwin City Public Library | B3: 2859 | C3: 633 | D3: 3492
A4: Basehor Community Library | B4: 7685 | C4: 1232 | D4: 8917
A5: Bern Community Library | B5: 148 | C5: 31 | D5: 179
A6: Bonner Springs City Library | B6: 5246 | C6: 907 | D6: 6153
A7: Burlingame Community Library | B7: 625 | C7: 256 | D7: 881
A8: Carbondale City Library | B8: 323 | C8: 128 | D8: 451
A9: Centralia Community Library | B9: 282 | C9: 94 | D9: 376
A10: Corning City Library | B10: 50 | D10: 50
A11: Digital Content
A12: Doniphan County Library - Elwood | B12: 55 | C12: 2 | D12: 57
A13: Doniphan County Library - Highland | B13: 161 | C13: 26 | D13: 187
A14: Doniphan County Library - Troy | B14: 560 | C14: 112 | D14: 672
A15: Doniphan County Library - Wathena | B15: 261 | C15: 52 | D15: 313
A16: Effingham Community Library | B16: 271 | C16: 57 | D16: 328
A17: Eudora Community Library | B17: 1367 | C17: 720 | D17: 2087
A18: Everest, Barnes Reading Room | B18: 92 | C18: 46 | D18: 138
A19: Hiawatha, Morrill Public Library | B19: 1743 | C19: 484 | D19: 2227
A20: Highland Community College | B20: 35 | C20: 5 | D20: 40
A21: Holton, Beck-Bookman Library | B21: 1711 | C21: 495 | D21: 2206
A22: Horton Public Library | B22: 230 | C22: 73 | D22: 303
A23: Lansing Community Library | B23: 2459 | C23: 797 | D23: 3256
... A25: Linwood Community Library | B25: 595 | C25: 160 | D25: 755
A26: Louisburg Library
A27: Lyndon Carnegie Library | B27: 370 | C27: 191 | D27: 561
A28: McLouth Public Library | B28: 293 | C28: 183 | D28: 476
A29: Meriden-Ozawkie Public Library | B29: 1467 | C29: 714 | D29: 2181
A30: Northeast Kansas Library System | B30: 16 | C30: 36 | D30: 52
A31: Nortonville Public Library | B31: 143 | C31: 41 | D31: 184
A32: Osage City Library | B32: 1416 | C32: 439 | D32: 1855
A33: Osawatomie Public Library | B33: 971 | C33: 366 | D33: 1337
A34: Oskaloosa Public Library | B34: 593 | C34: 178 | D34: 771
A35: Ottawa Library | B35: 6058 | C35: 1218 | D35: 7276
A36: Overbrook Public Library | B36: 687 | C36: 173 | D36: 860
A37: Paola Free Library | B37: 3439 | C37: 597 | D37: 4036
A38: Perry-Lecompton Community Library | B38: 164 | C38: 37 | D38: 201
... A54: Winchester Public Library | B54: 413 | C54: 381 | D54: 794
A55: Doniphan County Library - total | B55: =SUM(B12,B13,B14,B15) -> 1037 | C55: =SUM(C12,C13,C14,C15) -> 192 | D55: =SUM(D12,D13,D14,D15) -> 1229
A56: Prairie Hills Schools - total | B56: =SUM(B40,B41,B42,B43) -> 2581 | C56: =SUM(C40,C41,C42,C43) -> 19 | D56: =SUM(D40,D41,D42,D43) -> 2600

Sheet September
A1: Library | B1: Items owned by this library checked out at this library this month | C1: Items owned by other libraries checked out at this library this month | D1: Total circulation this month
A2: Atchison Public Library | B2: 4741 | C2: 1627 | D2: 6368
A3: Baldwin City Public Library | B3: 2582 | C3: 675 | D3: 3257
A4: Basehor Community Library | B4: 7350 | C4: 1234 | D4: 8584
A5: Bern Community Library | B5: 81 | C5: 20 | D5: 101
A6: Bonner Springs City Library | B6: 4986 | C6: 1023 | D6: 6009
A7: Burlingame Community Library | B7: 862 | C7: 271 | D7: 1133
A8: Carbondale City Library | B8: 356 | C8: 129 | D8: 485
A9: Centralia Community Library | B9: 227 | C9: 55 | D9: 282
A10: Corning City Library | B10: 42 | D10: 42
A11: Digital Content
A12: Doniphan County Library - Elwood | B12: 34 | C12: 12 | D12: 46
A13: Doniphan County Library - Highland | B13: 81 | C13: 29 | D13: 110
A14: Doniphan County Library - Troy | B14: 588 | C14: 170 | D14: 758
A15: Doniphan County Library - Wathena | B15: 186 | C15: 42 | D15: 228
A16: Effingham Community Library | B16: 254 | C16: 79 | D16: 333
A17: Eudora Community Library | B17: 1364 | C17: 665 | D17: 2029
A18: Everest, Barnes Reading Room | B18: 115 | C18: 84 | D18: 199
A19: Hiawatha, Morrill Public Library | B19: 1847 | C19: 676 | D19: 2523
A20: Highland Community College | B20: 39 | C20: 6 | D20: 45
A21: Holton, Beck-Bookman Library | B21: 1637 | C21: 621 | D21: 2258
A22: Horton Public Library | B22: 317 | C22: 63 | D22: 380
A23: Lansing Community Library | B23: 2021 | C23: 851 | D23: 2872
... A25: Linwood Community Library | B25: 492 | C25: 155 | D25: 647
A26: Louisburg Library
A27: Lyndon Carnegie Library | B27: 298 | C27: 126 | D27: 424
A28: McLouth Public Library | B28: 494 | C28: 300 | D28: 794
A29: Meriden-Ozawkie Public Library | B29: 1764 | C29: 837 | D29: 2601
A30: Northeast Kansas Library System | B30: 18 | C30: 22 | D30: 40
A31: Nortonville Public Library | B31: 195 | C31: 63 | D31: 258
A32: Osage City Library | B32: 1395 | C32: 552 | D32: 1947
A33: Osawatomie Public Library | B33: 817 | C33: 326 | D33: 1143
A34: Oskaloosa Public Library | B34: 137 | C34: 80 | D34: 217
A35: Ottawa Library | B35: 5742 | C35: 1038 | D35: 6780
A36: Overbrook Public Library | B36: 585 | C36: 149 | D36: 734
A37: Paola Free Library | B37: 2964 | C37: 593 | D37: 3557
A38: Perry-Lecompton Community Library | B38: 271 | C38: 32 | D38: 303
... A54: Winchester Public Library | B54: 326 | C54: 287 | D54: 613
A55: Doniphan County Library - total | B55: =SUM(B12,B13,B14,B15) -> 889 | C55: =SUM(C12,C13,C14,C15) -> 253 | D55: =SUM(D12,D13,D14,D15) -> 1142
A56: Prairie Hills Schools - total | B56: =SUM(B40,B41,B42,B43) -> 3244 | C56: =SUM(C40,C41,C42,C43) -> 75 | D56: =SUM(D40,D41,D42,D43) -> 3319

Sheet October
A1: Library | B1: Items owned by this library checked out at this library this month | C1: Items owned by other libraries checked out at this library this month | D1: Total circulation this month
A2: Atchison Public Library
A3: Baldwin City Public Library
A4: Basehor Community Library
A5: Bern Community Library
A6: Bonner Springs City Library
A7: Burlingame Community Library
A8: Carbondale City Library
A9: Centralia Community Library
A10: Corning City Library
A11: Digital Content
A12: Doniphan County Library - Elwood
A13: Doniphan County Library - Highland
... A54: Winchester Public Library
A55: Doniphan County Library - total | B55: =SUM(B12,B13,B14,B15) -> 0 | C55: =SUM(C12,C13,C14,C15) -> 0 | D55: =SUM(D12,D13,D14,D15) -> 0
A56: Prairie Hills Schools - total | B56: =SUM(B40,B41,B42,B43) -> 0 | C56: =SUM(C40,C41,C42,C43) -> 0 | D56: =SUM(D40,D41,D42,D43) -> 0

Sheet November
A1: Library | B1: Items owned by this library checked out at this library this month | C1: Items owned by other libraries checked out at this library this month | D1: Total circulation this month
A2: Atchison Public Library
A3: Baldwin City Public Library
A4: Basehor Community Library
A5: Bern Community Library
A6: Bonner Springs City Library
A7: Burlingame Community Library
A8: Carbondale City Library
A9: Centralia Community Library
A10: Corning City Library
A11: Digital Content
A12: Doniphan County Library - Elwood
A13: Doniphan County Library - Highland
... A54: Winchester Public Library
A55: Doniphan County Library - total | B55: =SUM(B12,B13,B14,B15) -> 0 | C55: =SUM(C12,C13,C14,C15) -> 0 | D55: =SUM(D12,D13,D14,D15) -> 0
A56: Prairie Hills Schools - total | B56: =SUM(B40,B41,B42,B43) -> 0 | C56: =SUM(C40,C41,C42,C43) -> 0 | D56: =SUM(D40,D41,D42,D43) -> 0

Sheet December
A1: Library | B1: Items owned by this library checked out at this library this month | C1: Items owned by other libraries checked out at this library this month | D1: Total circulation this month
A2: Atchison Public Library
A3: Baldwin City Public Library
A4: Basehor Community Library
A5: Bern Community Library
A6: Bonner Springs City Library
A7: Burlingame Community Library
A8: Carbondale City Library
A9: Centralia Community Library
A10: Corning City Library
A11: Digital Content
A12: Doniphan County Library - Elwood
A13: Doniphan County Library - Highland
... A54: Winchester Public Library
A55: Doniphan County Library - total | B55: =SUM(B12,B13,B14,B15) -> 0 | C55: =SUM(C12,C13,C14,C15) -> 0 | D55: =SUM(D12,D13,D14,D15) -> 0
A56: Prairie Hills Schools - total | B56: =SUM(B40,B41,B42,B43) -> 0 | C56: =SUM(C40,C41,C42,C43) -> 0 | D56: =SUM(D40,D41,D42,D43) -> 0

Sheet Yearly total
A1: Library | B1: Items owned by this library checked out at this library this month | C1: Items owned by other libraries checked out at this library this month | D1: Total circulation this month
A2: Atchison Public Library | B2: =SUM(January:December!B2) -> 40522 | C2: =SUM(January:December!C2) -> 13021 | D2: =SUM(January:December!D2) -> 53543
A3: Baldwin City Public Library | B3: =SUM(January:December!B3) -> 25507 | C3: =SUM(January:December!C3) -> 5798 | D3: =SUM(January:December!D3) -> 31305
A4: Basehor Community Library | B4: =SUM(January:December!B4) -> 70267 | C4: =SUM(January:December!C4) -> 10803 | D4: =SUM(January:December!D4) -> 81070
A5: Bern Community Library | B5: =SUM(January:December!B5) -> 1345 | C5: =SUM(January:December!C5) -> 215 | D5: =SUM(January:December!D5) -> 1560
A6: Bonner Springs City Library | B6: =SUM(January:December!B6) -> 49125 | C6: =SUM(January:December!C6) -> 8791 | D6: =SUM(January:December!D6) -> 57916
A7: Burlingame Community Library | B7: =SUM(January:December!B7) -> 5690 | C7: =SUM(January:December!C7) -> 2299 | D7: =SUM(January:December!D7) -> 7989
A8: Carbondale City Library | B8: =SUM(January:December!B8) -> 3658 | C8: =SUM(January:December!C8) -> 1058 | D8: =SUM(January:December!D8) -> 4716
A9: Centralia Community Library | B9: =SUM(January:December!B9) -> 2206 | C9: =SUM(January:December!C9) -> 569 | D9: =SUM(January:December!D9) -> 2775
A10: Corning City Library | B10: =SUM(January:December!B10) -> 469 | C10: =SUM(January:December!C10) -> 5 | D10: =SUM(January:December!D10) -> 474
A11: Digital Content | B11: =SUM(January:December!B11) -> 0 | C11: =SUM(January:December!C11) -> 0 | D11: =SUM(January:December!D11) -> 0
A12: Doniphan County Library - Elwood | B12: =SUM(January:December!B12) -> 321 | C12: =SUM(January:December!C12) -> 53 | D12: =SUM(January:December!D12) -> 374
A13: Doniphan County Library - Highland | B13: =SUM(January:December!B13) -> 1163 | C13: =SUM(January:December!C13) -> 378 | D13: =SUM(January:December!D13) -> 1541
... A54: Winchester Public Library | B54: =SUM(January:December!B54) -> 3339 | C54: =SUM(January:December!C54) -> 3356 | D54: =SUM(January:December!D54) -> 6695
A55: Doniphan County Library - total | B55: =SUM(B12,B13,B14,B15) -> 9289 | C55: =SUM(C12,C13,C14,C15) -> 2001 | D55: =SUM(D12,D13,D14,D15) -> 11290
A56: Prairie Hills Schools - total | B56: =SUM(B40,B41,B42,B43) -> 17516 | C56: =SUM(C40,C41,C42,C43) -> 692 | D56: =SUM(D40,D41,D42,D43) -> 18208
